Workbook
Name alpha: 'Параметри'!$B$3
Name delta: 'Параметри'!$B$4
Name bounds: 'Параметри'!$B$7:$B$10

Sheet Опис
A1: Книга ADMA: розрахунки статті, які можна перевірити вручну
A3: Кожне число на розрахункових аркушах є формулою Excel. Жовті клітинки - вхідні дані, які можна змінювати; блакитні клітинки - значення, перенесені з офіційних джерел (кожне з посиланням). Зміна жовтих клітинок на аркуші Параметри перераховує всі аркуші.
A4: Це українська версія книги excel/ADMA_workbook.xlsx: формули й числа однакові, перекладено підписи, назви аркушів і твердження анкети. Коди показників, шарів і країн не перекладаються.
A6: Аркуші та стаття
A7: Параметри: alpha, delta і межі рівнів, які використовують усі формули (розділ 3, таблиця 2).
A8: Калькулятор: введіть 21 відповідь анкети (1-5) і отримайте оцінки шарів, штраф, ADMI, рівень, DM_I, DM_S (рівняння 1-5).
A9: Приклад_розрахунку: профіль з початку розділу 4.
A10: Статистичний_режим: таблиці 5 і 6, харчова промисловість (NACE C10-C12) ЄС-27, Німеччини, дев'яти країн ЦСЄ та України (рівняння 6, P_min = 0). Використовує аркуші Дані_ЄС і Дані_України.
A11: TOPSIS: незалежне ранжування таблиці 6 (ентропійні ваги, близькість до ідеального рішення) і його кореляція Спірмена з ADMI.
A12: Дані_ЄС: значення Євростату для агрегату ЄС-27 і всіх 27 держав-членів; лідера визначають формулами MAX/INDEX/MATCH.
A13: Дані_України: значення Держстату з прямими посиланнями для завантаження.
A14: Діагностичні_ситуації: таблиця 4.
... A31: Книгу генерує scripts/build_workbook.py з data/raw, data/matrix.csv і data/generated; цей README генерується разом з аркушем Опис і має той самий зміст.

Sheet Параметри
A1: Параметри
A3: alpha | B3: 0.4 | C3: Сила штрафу за слабку ланку (каліброване значення)
A4: delta | B4: 0.375 | C4: Поріг критичної слабкості шару (каліброване значення; 0,375 = середня відповідь 2,5)
A6: Межі рівнів (таблиця 2)
A7: Рівень 1 | 2 | B7: 0.2
A8: Рівень 2 | 3 | B8: 0.4
A9: Рівень 3 | 4 | B9: 0.6
A10: Рівень 4 | 5 | B10: 0.8
A12: Початкові значення до калібрування: alpha = 0,50, delta = 0,25. Межі, скориговані за моделлю, для перевірки стійкості: 0,25, 0,45, 0,60, 0,80.

Sheet Калькулятор
A1: Калькулятор ADMI: введіть відповіді 1-5 у жовті клітинки
A3: # | B3: Блок | C3: Твердження | D3: Відповідь (1-5) | E3: Нормоване (рівн. 1)
A4: 1 | B4: C | C4: Програмне забезпечення для планування виробництва та ресурсів (ERP, MES) | D4: 3 | E4: =(D4-1)/4
A5: 2 | B5: C | C5: Автоматизація виробничих процесів за допомогою цифрового обладнання | D5: 3 | E5: =(D5-1)/4
A6: 3 | B6: C | C6: Затверджена стратегія або план цифрового розвитку на 2-3 роки | D6: 4 | E6: =(D6-1)/4
A7: 4 | B7: L1 | C7: Цифрові інструменти управління персоналом (HRM) | D7: 3 | E7: =(D7-1)/4
A8: 5 | B8: L1 | C8: Працівники мають навички роботи з цифровими інструментами | D8: 3 | E8: =(D8-1)/4
A9: 6 | B9: L1 | C9: Виробничий персонал вводить первинні дані на мобільних пристроях або терміналах на робочому місці | D9: 3 | E9: =(D9-1)/4
A10: 7 | B10: L2 | C10: Цифровий облік запасів (WMS або електронні таблиці) | D10: 3 | E10: =(D10-1)/4
A11: 8 | B11: L2 | C11: Збір і аналіз даних про використання ресурсів, відхилення та втрати | D11: 3 | E11: =(D11-1)/4
A12: 9 | B12: L2 | C12: Моніторинг умов зберігання за допомогою датчиків або IoT | D12: 3 | E12: =(D12-1)/4
A13: 10 | B13: L3 | C13: GPS-моніторинг або телематика на транспорті й техніці | D13: 2 | E13: =(D13-1)/4
A14: 11 | B14: L3 | C14: Планування технічного обслуговування на основі даних (CMMS) | D14: 1 | E14: =(D14-1)/4
A15: 12 | B15: L3 | C15: Технології точного землеробства або точного тваринництва | D15: 1 | E15: =(D15-1)/4
... A24: 21 | B24: S | C24: Оцінювання результатів цифрових проєктів і перегляд планів цифровізації | D24: 2 | E24: =(D24-1)/4
C26: Результат
C27: DM_C (рівн. 2) | D27: =AVERAGE(E4:E6)
C28: DM_L1 (рівн. 2) | D28: =AVERAGE(E7:E9)
C29: DM_L2 (рівн. 2) | D29: =AVERAGE(E10:E12)
C30: DM_L3 (рівн. 2) | D30: =AVERAGE(E13:E15)
C31: DM_L4 (рівн. 2) | D31: =AVERAGE(E16:E18)
C32: DM_I (інтеграція, поза індексом) | D32: =AVERAGE(E19:E21)
C33: DM_S (стратегія, поза індексом) | D33: =AVERAGE(E22:E24)
C34: ADMI_base (рівн. 3) | D34: =AVERAGE(D27:D31)
C35: DM_min | D35: =MIN(D27:D31)
C36: Штраф P (рівн. 4) | D36: =1-alpha*MAX(0,delta-D35)
C37: ADMI (рівн. 5) | D37: =D34*D36
C38: Рівень за ADMI_base | D38: =1+COUNTIF(bounds,"<"&ROUND(D34,12))
C39: Рівень за ADMI | D39: =1+COUNTIF(bounds,"<"&ROUND(D37,12))
C40: Штраф змінив рівень? | D40: =IF(D38<>D39,"так","ні")

Sheet Приклад_розрахунку
A1: Приклад розрахунку з розділу 4 (ADMI_base 0,433, рівень 3 -> ADMI 0,383, рівень 2)
A3: # | B3: Блок | C3: Твердження | D3: Відповідь (1-5) | E3: Нормоване (рівн. 1)
A4: 1 | B4: C | C4: Програмне забезпечення для планування виробництва та ресурсів (ERP, MES) | D4: 3 | E4: =(D4-1)/4
A5: 2 | B5: C | C5: Автоматизація виробничих процесів за допомогою цифрового обладнання | D5: 3 | E5: =(D5-1)/4
A6: 3 | B6: C | C6: Затверджена стратегія або план цифрового розвитку на 2-3 роки | D6: 4 | E6: =(D6-1)/4
A7: 4 | B7: L1 | C7: Цифрові інструменти управління персоналом (HRM) | D7: 3 | E7: =(D7-1)/4
A8: 5 | B8: L1 | C8: Працівники мають навички роботи з цифровими інструментами | D8: 3 | E8: =(D8-1)/4
A9: 6 | B9: L1 | C9: Виробничий персонал вводить первинні дані на мобільних пристроях або терміналах на робочому місці | D9: 3 | E9: =(D9-1)/4
A10: 7 | B10: L2 | C10: Цифровий облік запасів (WMS або електронні таблиці) | D10: 3 | E10: =(D10-1)/4
A11: 8 | B11: L2 | C11: Збір і аналіз даних про використання ресурсів, відхилення та втрати | D11: 3 | E11: =(D11-1)/4
A12: 9 | B12: L2 | C12: Моніторинг умов зберігання за допомогою датчиків або IoT | D12: 3 | E12: =(D12-1)/4
A13: 10 | B13: L3 | C13: GPS-моніторинг або телематика на транспорті й техніці | D13: 2 | E13: =(D13-1)/4
A14: 11 | B14: L3 | C14: Планування технічного обслуговування на основі даних (CMMS) | D14: 1 | E14: =(D14-1)/4
A15: 12 | B15: L3 | C15: Технології точного землеробства або точного тваринництва | D15: 1 | E15: =(D15-1)/4
... A24: 21 | B24: S | C24: Оцінювання результатів цифрових проєктів і перегляд планів цифровізації | D24: 2 | E24: =(D24-1)/4
C26: Результат
C27: DM_C (рівн. 2) | D27: =AVERAGE(E4:E6)
C28: DM_L1 (рівн. 2) | D28: =AVERAGE(E7:E9)
C29: DM_L2 (рівн. 2) | D29: =AVERAGE(E10:E12)
C30: DM_L3 (рівн. 2) | D30: =AVERAGE(E13:E15)
C31: DM_L4 (рівн. 2) | D31: =AVERAGE(E16:E18)
C32: DM_I (інтеграція, поза індексом) | D32: =AVERAGE(E19:E21)
C33: DM_S (стратегія, поза індексом) | D33: =AVERAGE(E22:E24)
C34: ADMI_base (рівн. 3) | D34: =AVERAGE(D27:D31)
C35: DM_min | D35: =MIN(D27:D31)
C36: Штраф P (рівн. 4) | D36: =1-alpha*MAX(0,delta-D35)
C37: ADMI (рівн. 5) | D37: =D34*D36
C38: Рівень за ADMI_base | D38: =1+COUNTIF(bounds,"<"&ROUND(D34,12))
C39: Рівень за ADMI | D39: =1+COUNTIF(bounds,"<"&ROUND(D37,12))
C40: Штраф змінив рівень? | D40: =IF(D38<>D39,"так","ні")

Sheet Статистичний_режим
A1: Таблиці 5 і 6. Статистичний режим ADMA для харчової промисловості (NACE C10-C12): оцінки шарів, індекс і ранжування (рівняння 6, P_min = 0)
A2: Верхня частина: кожен показник, поділений на значення лідера ЄС. Нижня частина: шари, ADMI і ранги. ЄС-27 і Німеччина - рядки для порівняння поза ранжуванням.
A3: Шар | B3: Показник | C3: Твердження | D3: Відповідність | E3: Рік ЄС | F3: Рік UA | G3: Лідер | H3: Лідер, % | I3: ЄС-27 | J3: Німеччина | K3: Польща | L3: Угорщина | M3: Румунія | N3: Чехія | O3: Словаччина | P3: Литва | Q3: Латвія | R3: Естонія | S3: Болгарія | T3: Україна
A4: C | B4: ERP | C4: 1 | D4: пряма | E4: ='Дані_ЄС'!B4 | F4: ='Дані_України'!D4 | G4: ='Дані_ЄС'!B36 | H4: ='Дані_ЄС'!B35 | I4: =IF('Дані_ЄС'!B6="","",'Дані_ЄС'!B6/$H4) | J4: =IF('Дані_ЄС'!B12="","",'Дані_ЄС'!B12/$H4) | K4: =IF('Дані_ЄС'!B28="","",'Дані_ЄС'!B28/$H4) | L4: =IF('Дані_ЄС'!B20="","",'Дані_ЄС'!B20/$H4) | M4: =IF('Дані_ЄС'!B30="","",'Дані_ЄС'!B30/$H4) | N4: =IF('Дані_ЄС'!B11="","",'Дані_ЄС'!B11/$H4) | O4: =IF('Дані_ЄС'!B33="","",'Дані_ЄС'!B33/$H4) | P4: =IF('Дані_ЄС'!B23="","",'Дані_ЄС'!B23/$H4) | Q4: =IF('Дані_ЄС'!B25="","",'Дані_ЄС'!B25/$H4) | R4: =IF('Дані_ЄС'!B14="","",'Дані_ЄС'!B14/$H4) | S4: =IF('Дані_ЄС'!B9="","",'Дані_ЄС'!B9/$H4) | T4: =IF('Дані_України'!E4="","",'Дані_України'!E4/$H4)
A5: C | B5: IOT_PRODUCTION | C5: 2 | D5: прийнятна | E5: ='Дані_ЄС'!C4 | F5: ='Дані_України'!D5 | G5: ='Дані_ЄС'!C36 | H5: ='Дані_ЄС'!C35 | I5: =IF('Дані_ЄС'!C6="","",'Дані_ЄС'!C6/$H5) | J5: =IF('Дані_ЄС'!C12="","",'Дані_ЄС'!C12/$H5) | K5: =IF('Дані_ЄС'!C28="","",'Дані_ЄС'!C28/$H5) | L5: =IF('Дані_ЄС'!C20="","",'Дані_ЄС'!C20/$H5) | M5: =IF('Дані_ЄС'!C30="","",'Дані_ЄС'!C30/$H5) | N5: =IF('Дані_ЄС'!C11="","",'Дані_ЄС'!C11/$H5) | O5: =IF('Дані_ЄС'!C33="","",'Дані_ЄС'!C33/$H5) | P5: =IF('Дані_ЄС'!C23="","",'Дані_ЄС'!C23/$H5) | Q5: =IF('Дані_ЄС'!C25="","",'Дані_ЄС'!C25/$H5) | R5: =IF('Дані_ЄС'!C14="","",'Дані_ЄС'!C14/$H5) | S5: =IF('Дані_ЄС'!C9="","",'Дані_ЄС'!C9/$H5) | T5: =IF('Дані_України'!E5="","",'Дані_України'!E5/$H5)
A6: C | B6: ICT_SECURITY_DOCUMENT | C6: 3 | D6: проксі | E6: ='Дані_ЄС'!D4 | F6: ='Дані_України'!D6 | G6: ='Дані_ЄС'!D36 | H6: ='Дані_ЄС'!D35 | I6: =IF('Дані_ЄС'!D6="","",'Дані_ЄС'!D6/$H6) | J6: =IF('Дані_ЄС'!D12="","",'Дані_ЄС'!D12/$H6) | K6: =IF('Дані_ЄС'!D28="","",'Дані_ЄС'!D28/$H6) | L6: =IF('Дані_ЄС'!D20="","",'Дані_ЄС'!D20/$H6) | M6: =IF('Дані_ЄС'!D30="","",'Дані_ЄС'!D30/$H6) | N6: =IF('Дані_ЄС'!D11="","",'Дані_ЄС'!D11/$H6) | O6: =IF('Дані_ЄС'!D33="","",'Дані_ЄС'!D33/$H6) | P6: =IF('Дані_ЄС'!D23="","",'Дані_ЄС'!D23/$H6) | Q6: =IF('Дані_ЄС'!D25="","",'Дані_ЄС'!D25/$H6) | R6: =IF('Дані_ЄС'!D14="","",'Дані_ЄС'!D14/$H6) | S6: =IF('Дані_ЄС'!D9="","",'Дані_ЄС'!D9/$H6) | T6: =IF('Дані_України'!E6="","",'Дані_України'!E6/$H6)
A7: L1 | B7: ICT_TRAINING_ICT_SPECIALISTS | C7: 5 | D7: прийнятна | E7: ='Дані_ЄС'!E4 | F7: ='Дані_України'!D7 | G7: ='Дані_ЄС'!E36 | H7: ='Дані_ЄС'!E35 | I7: =IF('Дані_ЄС'!E6="","",'Дані_ЄС'!E6/$H7) | J7: =IF('Дані_ЄС'!E12="","",'Дані_ЄС'!E12/$H7) | K7: =IF('Дані_ЄС'!E28="","",'Дані_ЄС'!E28/$H7) | L7: =IF('Дані_ЄС'!E20="","",'Дані_ЄС'!E20/$H7) | M7: =IF('Дані_ЄС'!E30="","",'Дані_ЄС'!E30/$H7) | N7: =IF('Дані_ЄС'!E11="","",'Дані_ЄС'!E11/$H7) | O7: =IF('Дані_ЄС'!E33="","",'Дані_ЄС'!E33/$H7) | P7: =IF('Дані_ЄС'!E23="","",'Дані_ЄС'!E23/$H7) | Q7: =IF('Дані_ЄС'!E25="","",'Дані_ЄС'!E25/$H7) | R7: =IF('Дані_ЄС'!E14="","",'Дані_ЄС'!E14/$H7) | S7: =IF('Дані_ЄС'!E9="","",'Дані_ЄС'!E9/$H7) | T7: =IF('Дані_України'!E7="","",'Дані_України'!E7/$H7)
A8: L1 | B8: ICT_TRAINING_OTHER_EMPLOYEES | C8: 5 | D8: прийнятна | E8: ='Дані_ЄС'!F4 | F8: ='Дані_України'!D8 | G8: ='Дані_ЄС'!F36 | H8: ='Дані_ЄС'!F35 | I8: =IF('Дані_ЄС'!F6="","",'Дані_ЄС'!F6/$H8) | J8: =IF('Дані_ЄС'!F12="","",'Дані_ЄС'!F12/$H8) | K8: =IF('Дані_ЄС'!F28="","",'Дані_ЄС'!F28/$H8) | L8: =IF('Дані_ЄС'!F20="","",'Дані_ЄС'!F20/$H8) | M8: =IF('Дані_ЄС'!F30="","",'Дані_ЄС'!F30/$H8) | N8: =IF('Дані_ЄС'!F11="","",'Дані_ЄС'!F11/$H8) | O8: =IF('Дані_ЄС'!F33="","",'Дані_ЄС'!F33/$H8) | P8: =IF('Дані_ЄС'!F23="","",'Дані_ЄС'!F23/$H8) | Q8: =IF('Дані_ЄС'!F25="","",'Дані_ЄС'!F25/$H8) | R8: =IF('Дані_ЄС'!F14="","",'Дані_ЄС'!F14/$H8) | S8: =IF('Дані_ЄС'!F9="","",'Дані_ЄС'!F9/$H8) | T8: =IF('Дані_України'!E8="","",'Дані_України'!E8/$H8)
A9: L2 | B9: SUPPLY_CHAIN_DATA_EXCHANGE | C9: 7 | D9: проксі | E9: ='Дані_ЄС'!G4 | F9: ='Дані_України'!D9 | G9: ='Дані_ЄС'!G36 | H9: ='Дані_ЄС'!G35 | I9: =IF('Дані_ЄС'!G6="","",'Дані_ЄС'!G6/$H9) | J9: =IF('Дані_ЄС'!G12="","",'Дані_ЄС'!G12/$H9) | K9: =IF('Дані_ЄС'!G28="","",'Дані_ЄС'!G28/$H9) | L9: =IF('Дані_ЄС'!G20="","",'Дані_ЄС'!G20/$H9) | M9: =IF('Дані_ЄС'!G30="","",'Дані_ЄС'!G30/$H9) | N9: =IF('Дані_ЄС'!G11="","",'Дані_ЄС'!G11/$H9) | O9: =IF('Дані_ЄС'!G33="","",'Дані_ЄС'!G33/$H9) | P9: =IF('Дані_ЄС'!G23="","",'Дані_ЄС'!G23/$H9) | Q9: =IF('Дані_ЄС'!G25="","",'Дані_ЄС'!G25/$H9) | R9: =IF('Дані_ЄС'!G14="","",'Дані_ЄС'!G14/$H9) | S9: =IF('Дані_ЄС'!G9="","",'Дані_ЄС'!G9/$H9) | T9: =IF('Дані_України'!E9="","",'Дані_України'!E9/$H9)
A10: L2 | B10: DATA_ANALYTICS | C10: 8 | D10: прийнятна | E10: ='Дані_ЄС'!H4 | F10: ='Дані_України'!D10 | G10: ='Дані_ЄС'!H36 | H10: ='Дані_ЄС'!H35 | I10: =IF('Дані_ЄС'!H6="","",'Дані_ЄС'!H6/$H10) | J10: =IF('Дані_ЄС'!H12="","",'Дані_ЄС'!H12/$H10) | K10: =IF('Дані_ЄС'!H28="","",'Дані_ЄС'!H28/$H10) | L10: =IF('Дані_ЄС'!H20="","",'Дані_ЄС'!H20/$H10) | M10: =IF('Дані_ЄС'!H30="","",'Дані_ЄС'!H30/$H10) | N10: =IF('Дані_ЄС'!H11="","",'Дані_ЄС'!H11/$H10) | O10: =IF('Дані_ЄС'!H33="","",'Дані_ЄС'!H33/$H10) | P10: =IF('Дані_ЄС'!H23="","",'Дані_ЄС'!H23/$H10) | Q10: =IF('Дані_ЄС'!H25="","",'Дані_ЄС'!H25/$H10) | R10: =IF('Дані_ЄС'!H14="","",'Дані_ЄС'!H14/$H10) | S10: =IF('Дані_ЄС'!H9="","",'Дані_ЄС'!H9/$H10) | T10: =IF('Дані_України'!E10="","",'Дані_України'!E10/$H10)
A11: L2 | B11: IOT_ANY | C11: 9 | D11: прийнятна | E11: ='Дані_ЄС'!I4 | F11: ='Дані_України'!D11 | G11: ='Дані_ЄС'!I36 | H11: ='Дані_ЄС'!I35 | I11: =IF('Дані_ЄС'!I6="","",'Дані_ЄС'!I6/$H11) | J11: =IF('Дані_ЄС'!I12="","",'Дані_ЄС'!I12/$H11) | K11: =IF('Дані_ЄС'!I28="","",'Дані_ЄС'!I28/$H11) | L11: =IF('Дані_ЄС'!I20="","",'Дані_ЄС'!I20/$H11) | M11: =IF('Дані_ЄС'!I30="","",'Дані_ЄС'!I30/$H11) | N11: =IF('Дані_ЄС'!I11="","",'Дані_ЄС'!I11/$H11) | O11: =IF('Дані_ЄС'!I33="","",'Дані_ЄС'!I33/$H11) | P11: =IF('Дані_ЄС'!I23="","",'Дані_ЄС'!I23/$H11) | Q11: =IF('Дані_ЄС'!I25="","",'Дані_ЄС'!I25/$H11) | R11: =IF('Дані_ЄС'!I14="","",'Дані_ЄС'!I14/$H11) | S11: =IF('Дані_ЄС'!I9="","",'Дані_ЄС'!I9/$H11) | T11: =IF('Дані_України'!E11="","",'Дані_України'!E11/$H11)
A12: L3 | B12: MOBILE_INTERNET | C12: 10 | D12: проксі | E12: ='Дані_ЄС'!J4 | F12: ='Дані_України'!D12 | G12: ='Дані_ЄС'!J36 | H12: ='Дані_ЄС'!J35 | I12: =IF('Дані_ЄС'!J6="","",'Дані_ЄС'!J6/$H12) | J12: =IF('Дані_ЄС'!J12="","",'Дані_ЄС'!J12/$H12) | K12: =IF('Дані_ЄС'!J28="","",'Дані_ЄС'!J28/$H12) | L12: =IF('Дані_ЄС'!J20="","",'Дані_ЄС'!J20/$H12) | M12: =IF('Дані_ЄС'!J30="","",'Дані_ЄС'!J30/$H12) | N12: =IF('Дані_ЄС'!J11="","",'Дані_ЄС'!J11/$H12) | O12: =IF('Дані_ЄС'!J33="","",'Дані_ЄС'!J33/$H12) | P12: =IF('Дані_ЄС'!J23="","",'Дані_ЄС'!J23/$H12) | Q12: =IF('Дані_ЄС'!J25="","",'Дані_ЄС'!J25/$H12) | R12: =IF('Дані_ЄС'!J14="","",'Дані_ЄС'!J14/$H12) | S12: =IF('Дані_ЄС'!J9="","",'Дані_ЄС'!J9/$H12) | T12: =IF('Дані_України'!E12="","",'Дані_України'!E12/$H12)
A13: L3 | B13: PAID_CLOUD | C13: 11 | D13: проксі | E13: ='Дані_ЄС'!K4 | F13: ='Дані_України'!D13 | G13: ='Дані_ЄС'!K36 | H13: ='Дані_ЄС'!K35 | I13: =IF('Дані_ЄС'!K6="","",'Дані_ЄС'!K6/$H13) | J13: =IF('Дані_ЄС'!K12="","",'Дані_ЄС'!K12/$H13) | K13: =IF('Дані_ЄС'!K28="","",'Дані_ЄС'!K28/$H13) | L13: =IF('Дані_ЄС'!K20="","",'Дані_ЄС'!K20/$H13) | M13: =IF('Дані_ЄС'!K30="","",'Дані_ЄС'!K30/$H13) | N13: =IF('Дані_ЄС'!K11="","",'Дані_ЄС'!K11/$H13) | O13: =IF('Дані_ЄС'!K33="","",'Дані_ЄС'!K33/$H13) | P13: =IF('Дані_ЄС'!K23="","",'Дані_ЄС'!K23/$H13) | Q13: =IF('Дані_ЄС'!K25="","",'Дані_ЄС'!K25/$H13) | R13: =IF('Дані_ЄС'!K14="","",'Дані_ЄС'!K14/$H13) | S13: =IF('Дані_ЄС'!K9="","",'Дані_ЄС'!K9/$H13) | T13: =IF('Дані_України'!E13="","",'Дані_України'!E13/$H13)
A14: L4 | B14: ECOMMERCE_SALES | C14: 13 | D14: пряма | E14: ='Дані_ЄС'!L4 | F14: ='Дані_України'!D14 | G14: ='Дані_ЄС'!L36 | H14: ='Дані_ЄС'!L35 | I14: =IF('Дані_ЄС'!L6="","",'Дані_ЄС'!L6/$H14) | J14: =IF('Дані_ЄС'!L12="","",'Дані_ЄС'!L12/$H14) | K14: =IF('Дані_ЄС'!L28="","",'Дані_ЄС'!L28/$H14) | L14: =IF('Дані_ЄС'!L20="","",'Дані_ЄС'!L20/$H14) | M14: =IF('Дані_ЄС'!L30="","",'Дані_ЄС'!L30/$H14) | N14: =IF('Дані_ЄС'!L11="","",'Дані_ЄС'!L11/$H14) | O14: =IF('Дані_ЄС'!L33="","",'Дані_ЄС'!L33/$H14) | P14: =IF('Дані_ЄС'!L23="","",'Дані_ЄС'!L23/$H14) | Q14: =IF('Дані_ЄС'!L25="","",'Дані_ЄС'!L25/$H14) | R14: =IF('Дані_ЄС'!L14="","",'Дані_ЄС'!L14/$H14) | S14: =IF('Дані_ЄС'!L9="","",'Дані_ЄС'!L9/$H14) | T14: =IF('Дані_України'!E14="","",'Дані_України'!E14/$H14)
A15: L4 | B15: WEBSITE | C15: 13 | D15: пряма | E15: ='Дані_ЄС'!M4 | F15: ='Дані_України'!D15 | G15: ='Дані_ЄС'!M36 | H15: ='Дані_ЄС'!M35 | I15: =IF('Дані_ЄС'!M6="","",'Дані_ЄС'!M6/$H15) | J15: =IF('Дані_ЄС'!M12="","",'Дані_ЄС'!M12/$H15) | K15: =IF('Дані_ЄС'!M28="","",'Дані_ЄС'!M28/$H15) | L15: =IF('Дані_ЄС'!M20="","",'Дані_ЄС'!M20/$H15) | M15: =IF('Дані_ЄС'!M30="","",'Дані_ЄС'!M30/$H15) | N15: =IF('Дані_ЄС'!M11="","",'Дані_ЄС'!M11/$H15) | O15: =IF('Дані_ЄС'!M33="","",'Дані_ЄС'!M33/$H15) | P15: =IF('Дані_ЄС'!M23="","",'Дані_ЄС'!M23/$H15) | Q15: =IF('Дані_ЄС'!M25="","",'Дані_ЄС'!M25/$H15) | R15: =IF('Дані_ЄС'!M14="","",'Дані_ЄС'!M14/$H15) | S15: =IF('Дані_ЄС'!M9="","",'Дані_ЄС'!M9/$H15) | T15: =IF('Дані_України'!E15="","",'Дані_України'!E15/$H15)
A16: L4 | B16: CRM | C16: 14 | D16: пряма | E16: ='Дані_ЄС'!N4 | F16: ='Дані_України'!D16 | G16: ='Дані_ЄС'!N36 | H16: ='Дані_ЄС'!N35 | I16: =IF('Дані_ЄС'!N6="","",'Дані_ЄС'!N6/$H16) | J16: =IF('Дані_ЄС'!N12="","",'Дані_ЄС'!N12/$H16) | K16: =IF('Дані_ЄС'!N28="","",'Дані_ЄС'!N28/$H16) | L16: =IF('Дані_ЄС'!N20="","",'Дані_ЄС'!N20/$H16) | M16: =IF('Дані_ЄС'!N30="","",'Дані_ЄС'!N30/$H16) | N16: =IF('Дані_ЄС'!N11="","",'Дані_ЄС'!N11/$H16) | O16: =IF('Дані_ЄС'!N33="","",'Дані_ЄС'!N33/$H16) | P16: =IF('Дані_ЄС'!N23="","",'Дані_ЄС'!N23/$H16) | Q16: =IF('Дані_ЄС'!N25="","",'Дані_ЄС'!N25/$H16) | R16: =IF('Дані_ЄС'!N14="","",'Дані_ЄС'!N14/$H16) | S16: =IF('Дані_ЄС'!N9="","",'Дані_ЄС'!N9/$H16) | T16: =IF('Дані_України'!E16="","",'Дані_України'!E16/$H16)
A17: I | B17: EINVOICE_AUTOMATED | C17: 16 | D17: проксі | E17: ='Дані_ЄС'!O4 | F17: ='Дані_України'!D17 | G17: ='Дані_ЄС'!O36 | H17: ='Дані_ЄС'!O35 | I17: =IF('Дані_ЄС'!O6="","",'Дані_ЄС'!O6/$H17) | J17: =IF('Дані_ЄС'!O12="","",'Дані_ЄС'!O12/$H17) | K17: =IF('Дані_ЄС'!O28="","",'Дані_ЄС'!O28/$H17) | L17: =IF('Дані_ЄС'!O20="","",'Дані_ЄС'!O20/$H17) | M17: =IF('Дані_ЄС'!O30="","",'Дані_ЄС'!O30/$H17) | N17: =IF('Дані_ЄС'!O11="","",'Дані_ЄС'!O11/$H17) | O17: =IF('Дані_ЄС'!O33="","",'Дані_ЄС'!O33/$H17) | P17: =IF('Дані_ЄС'!O23="","",'Дані_ЄС'!O23/$H17) | Q17: =IF('Дані_ЄС'!O25="","",'Дані_ЄС'!O25/$H17) | R17: =IF('Дані_ЄС'!O14="","",'Дані_ЄС'!O14/$H17) | S17: =IF('Дані_ЄС'!O9="","",'Дані_ЄС'!O9/$H17) | T17: =IF('Дані_України'!E17="","",'Дані_України'!E17/$H17)
A18: I | B18: BI | C18: 18 | D18: проксі | E18: ='Дані_ЄС'!P4 | F18: ='Дані_України'!D18 | G18: ='Дані_ЄС'!P36 | H18: ='Дані_ЄС'!P35 | I18: =IF('Дані_ЄС'!P6="","",'Дані_ЄС'!P6/$H18) | J18: =IF('Дані_ЄС'!P12="","",'Дані_ЄС'!P12/$H18) | K18: =IF('Дані_ЄС'!P28="","",'Дані_ЄС'!P28/$H18) | L18: =IF('Дані_ЄС'!P20="","",'Дані_ЄС'!P20/$H18) | M18: =IF('Дані_ЄС'!P30="","",'Дані_ЄС'!P30/$H18) | N18: =IF('Дані_ЄС'!P11="","",'Дані_ЄС'!P11/$H18) | O18: =IF('Дані_ЄС'!P33="","",'Дані_ЄС'!P33/$H18) | P18: =IF('Дані_ЄС'!P23="","",'Дані_ЄС'!P23/$H18) | Q18: =IF('Дані_ЄС'!P25="","",'Дані_ЄС'!P25/$H18) | R18: =IF('Дані_ЄС'!P14="","",'Дані_ЄС'!P14/$H18) | S18: =IF('Дані_ЄС'!P9="","",'Дані_ЄС'!P9/$H18) | T18: =IF('Дані_України'!E18="","",'Дані_України'!E18/$H18)
A19: S | B19: AI_ANY | C19: 19 | D19: проксі | E19: ='Дані_ЄС'!Q4 | F19: ='Дані_України'!D19 | G19: ='Дані_ЄС'!Q36 | H19: ='Дані_ЄС'!Q35 | I19: =IF('Дані_ЄС'!Q6="","",'Дані_ЄС'!Q6/$H19) | J19: =IF('Дані_ЄС'!Q12="","",'Дані_ЄС'!Q12/$H19) | K19: =IF('Дані_ЄС'!Q28="","",'Дані_ЄС'!Q28/$H19) | L19: =IF('Дані_ЄС'!Q20="","",'Дані_ЄС'!Q20/$H19) | M19: =IF('Дані_ЄС'!Q30="","",'Дані_ЄС'!Q30/$H19) | N19: =IF('Дані_ЄС'!Q11="","",'Дані_ЄС'!Q11/$H19) | O19: =IF('Дані_ЄС'!Q33="","",'Дані_ЄС'!Q33/$H19) | P19: =IF('Дані_ЄС'!Q23="","",'Дані_ЄС'!Q23/$H19) | Q19: =IF('Дані_ЄС'!Q25="","",'Дані_ЄС'!Q25/$H19) | R19: =IF('Дані_ЄС'!Q14="","",'Дані_ЄС'!Q14/$H19) | S19: =IF('Дані_ЄС'!Q9="","",'Дані_ЄС'!Q9/$H19) | T19: =IF('Дані_України'!E19="","",'Дані_України'!E19/$H19)
A20: S | B20: DII_BASIC_V3 | C20: 20 | D20: проксі | E20: ='Дані_ЄС'!R4 | F20: ='Дані_України'!D20 | G20: ='Дані_ЄС'!R36 | H20: ='Дані_ЄС'!R35 | I20: =IF('Дані_ЄС'!R6="","",'Дані_ЄС'!R6/$H20) | J20: =IF('Дані_ЄС'!R12="","",'Дані_ЄС'!R12/$H20) | K20: =IF('Дані_ЄС'!R28="","",'Дані_ЄС'!R28/$H20) | L20: =IF('Дані_ЄС'!R20="","",'Дані_ЄС'!R20/$H20) | M20: =IF('Дані_ЄС'!R30="","",'Дані_ЄС'!R30/$H20) | N20: =IF('Дані_ЄС'!R11="","",'Дані_ЄС'!R11/$H20) | O20: =IF('Дані_ЄС'!R33="","",'Дані_ЄС'!R33/$H20) | P20: =IF('Дані_ЄС'!R23="","",'Дані_ЄС'!R23/$H20) | Q20: =IF('Дані_ЄС'!R25="","",'Дані_ЄС'!R25/$H20) | R20: =IF('Дані_ЄС'!R14="","",'Дані_ЄС'!R14/$H20) | S20: =IF('Дані_ЄС'!R9="","",'Дані_ЄС'!R9/$H20) | T20: =IF('Дані_України'!E20="","",'Дані_України'!E20/$H20)
A23: Об'єкт | B23: C | C23: L1 | D23: L2 | E23: L3 | F23: L4 | G23: ADMI_base | H23: DM_min | I23: Штраф | J23: ADMI | K23: Рівень | L23: DM_I | M23: DM_S | N23: Ранг ADMI | O23: Ранг TOPSIS
A24: ЄС-27 | B24: =AVERAGEIF($A$4:$A$20,"C",I$4:I$20) | C24: =AVERAGEIF($A$4:$A$20,"L1",I$4:I$20) | D24: =AVERAGEIF($A$4:$A$20,"L2",I$4:I$20) | E24: =AVERAGEIF($A$4:$A$20,"L3",I$4:I$20) | F24: =AVERAGEIF($A$4:$A$20,"L4",I$4:I$20) | G24: =AVERAGE(B24:F24) | H24: =MIN(B24:F24) | I24: =1-alpha*MAX(0,delta-H24) | J24: =G24*I24 | K24: =1+COUNTIF(bounds,"<"&ROUND(J24,12)) | L24: =AVERAGEIF($A$4:$A$20,"I",I$4:I$20) | M24: =AVERAGEIF($A$4:$A$20,"S",I$4:I$20) | N24: - | O24: -
A25: Німеччина | B25: =AVERAGEIF($A$4:$A$20,"C",J$4:J$20) | C25: =AVERAGEIF($A$4:$A$20,"L1",J$4:J$20) | D25: =AVERAGEIF($A$4:$A$20,"L2",J$4:J$20) | E25: =AVERAGEIF($A$4:$A$20,"L3",J$4:J$20) | F25: =AVERAGEIF($A$4:$A$20,"L4",J$4:J$20) | G25: =AVERAGE(B25:F25) | H25: =MIN(B25:F25) | I25: =1-alpha*MAX(0,delta-H25) | J25: =G25*I25 | K25: =1+COUNTIF(bounds,"<"&ROUND(J25,12)) | L25: =AVERAGEIF($A$4:$A$20,"I",J$4:J$20) | M25: =AVERAGEIF($A$4:$A$20,"S",J$4:J$20) | N25: - | O25: -
A26: Польща | B26: =AVERAGEIF($A$4:$A$20,"C",K$4:K$20) | C26: =AVERAGEIF($A$4:$A$20,"L1",K$4:K$20) | D26: =AVERAGEIF($A$4:$A$20,"L2",K$4:K$20) | E26: =AVERAGEIF($A$4:$A$20,"L3",K$4:K$20) | F26: =AVERAGEIF($A$4:$A$20,"L4",K$4:K$20) | G26: =AVERAGE(B26:F26) | H26: =MIN(B26:F26) | I26: =1-alpha*MAX(0,delta-H26) | J26: =G26*I26 | K26: =1+COUNTIF(bounds,"<"&ROUND(J26,12)) | L26: =AVERAGEIF($A$4:$A$20,"I",K$4:K$20) | M26: =AVERAGEIF($A$4:$A$20,"S",K$4:K$20) | N26: =1+COUNTIF($J$26:$J$35,">"&J26) | O26: ='TOPSIS'!AC5
A27: Угорщина | B27: =AVERAGEIF($A$4:$A$20,"C",L$4:L$20) | C27: =AVERAGEIF($A$4:$A$20,"L1",L$4:L$20) | D27: =AVERAGEIF($A$4:$A$20,"L2",L$4:L$20) | E27: =AVERAGEIF($A$4:$A$20,"L3",L$4:L$20) | F27: =AVERAGEIF($A$4:$A$20,"L4",L$4:L$20) | G27: =AVERAGE(B27:F27) | H27: =MIN(B27:F27) | I27: =1-alpha*MAX(0,delta-H27) | J27: =G27*I27 | K27: =1+COUNTIF(bounds,"<"&ROUND(J27,12)) | L27: =AVERAGEIF($A$4:$A$20,"I",L$4:L$20) | M27: =AVERAGEIF($A$4:$A$20,"S",L$4:L$20) | N27: =1+COUNTIF($J$26:$J$35,">"&J27) | O27: ='TOPSIS'!AC6
A28: Румунія | B28: =AVERAGEIF($A$4:$A$20,"C",M$4:M$20) | C28: =AVERAGEIF($A$4:$A$20,"L1",M$4:M$20) | D28: =AVERAGEIF($A$4:$A$20,"L2",M$4:M$20) | E28: =AVERAGEIF($A$4:$A$20,"L3",M$4:M$20) | F28: =AVERAGEIF($A$4:$A$20,"L4",M$4:M$20) | G28: =AVERAGE(B28:F28) | H28: =MIN(B28:F28) | I28: =1-alpha*MAX(0,delta-H28) | J28: =G28*I28 | K28: =1+COUNTIF(bounds,"<"&ROUND(J28,12)) | L28: =AVERAGEIF($A$4:$A$20,"I",M$4:M$20) | M28: =AVERAGEIF($A$4:$A$20,"S",M$4:M$20) | N28: =1+COUNTIF($J$26:$J$35,">"&J28) | O28: ='TOPSIS'!AC7
A29: Чехія | B29: =AVERAGEIF($A$4:$A$20,"C",N$4:N$20) | C29: =AVERAGEIF($A$4:$A$20,"L1",N$4:N$20) | D29: =AVERAGEIF($A$4:$A$20,"L2",N$4:N$20) | E29: =AVERAGEIF($A$4:$A$20,"L3",N$4:N$20) | F29: =AVERAGEIF($A$4:$A$20,"L4",N$4:N$20) | G29: =AVERAGE(B29:F29) | H29: =MIN(B29:F29) | I29: =1-alpha*MAX(0,delta-H29) | J29: =G29*I29 | K29: =1+COUNTIF(bounds,"<"&ROUND(J29,12)) | L29: =AVERAGEIF($A$4:$A$20,"I",N$4:N$20) | M29: =AVERAGEIF($A$4:$A$20,"S",N$4:N$20) | N29: =1+COUNTIF($J$26:$J$35,">"&J29) | O29: ='TOPSIS'!AC8
A30: Словаччина | B30: =AVERAGEIF($A$4:$A$20,"C",O$4:O$20) | C30: =AVERAGEIF($A$4:$A$20,"L1",O$4:O$20) | D30: =AVERAGEIF($A$4:$A$20,"L2",O$4:O$20) | E30: =AVERAGEIF($A$4:$A$20,"L3",O$4:O$20) | F30: =AVERAGEIF($A$4:$A$20,"L4",O$4:O$20) | G30: =AVERAGE(B30:F30) | H30: =MIN(B30:F30) | I30: =1-alpha*MAX(0,delta-H30) | J30: =G30*I30 | K30: =1+COUNTIF(bounds,"<"&ROUND(J30,12)) | L30: =AVERAGEIF($A$4:$A$20,"I",O$4:O$20) | M30: =AVERAGEIF($A$4:$A$20,"S",O$4:O$20) | N30: =1+COUNTIF($J$26:$J$35,">"&J30) | O30: ='TOPSIS'!AC9
A31: Литва | B31: =AVERAGEIF($A$4:$A$20,"C",P$4:P$20) | C31: =AVERAGEIF($A$4:$A$20,"L1",P$4:P$20) | D31: =AVERAGEIF($A$4:$A$20,"L2",P$4:P$20) | E31: =AVERAGEIF($A$4:$A$20,"L3",P$4:P$20) | F31: =AVERAGEIF($A$4:$A$20,"L4",P$4:P$20) | G31: =AVERAGE(B31:F31) | H31: =MIN(B31:F31) | I31: =1-alpha*MAX(0,delta-H31) | J31: =G31*I31 | K31: =1+COUNTIF(bounds,"<"&ROUND(J31,12)) | L31: =AVERAGEIF($A$4:$A$20,"I",P$4:P$20) | M31: =AVERAGEIF($A$4:$A$20,"S",P$4:P$20) | N31: =1+COUNTIF($J$26:$J$35,">"&J31) | O31: ='TOPSIS'!AC10
A32: Латвія | B32: =AVERAGEIF($A$4:$A$20,"C",Q$4:Q$20) | C32: =AVERAGEIF($A$4:$A$20,"L1",Q$4:Q$20) | D32: =AVERAGEIF($A$4:$A$20,"L2",Q$4:Q$20) | E32: =AVERAGEIF($A$4:$A$20,"L3",Q$4:Q$20) | F32: =AVERAGEIF($A$4:$A$20,"L4",Q$4:Q$20) | G32: =AVERAGE(B32:F32) | H32: =MIN(B32:F32) | I32: =1-alpha*MAX(0,delta-H32) | J32: =G32*I32 | K32: =1+COUNTIF(bounds,"<"&ROUND(J32,12)) | L32: =AVERAGEIF($A$4:$A$20,"I",Q$4:Q$20) | M32: =AVERAGEIF($A$4:$A$20,"S",Q$4:Q$20) | N32: =1+COUNTIF($J$26:$J$35,">"&J32) | O32: ='TOPSIS'!AC11
A33: Естонія | B33: =AVERAGEIF($A$4:$A$20,"C",R$4:R$20) | C33: =AVERAGEIF($A$4:$A$20,"L1",R$4:R$20) | D33: =AVERAGEIF($A$4:$A$20,"L2",R$4:R$20) | E33: =AVERAGEIF($A$4:$A$20,"L3",R$4:R$20) | F33: =AVERAGEIF($A$4:$A$20,"L4",R$4:R$20) | G33: =AVERAGE(B33:F33) | H33: =MIN(B33:F33) | I33: =1-alpha*MAX(0,delta-H33) | J33: =G33*I33 | K33: =1+COUNTIF(bounds,"<"&ROUND(J33,12)) | L33: =AVERAGEIF($A$4:$A$20,"I",R$4:R$20) | M33: =AVERAGEIF($A$4:$A$20,"S",R$4:R$20) | N33: =1+COUNTIF($J$26:$J$35,">"&J33) | O33: ='TOPSIS'!AC12
A34: Болгарія | B34: =AVERAGEIF($A$4:$A$20,"C",S$4:S$20) | C34: =AVERAGEIF($A$4:$A$20,"L1",S$4:S$20) | D34: =AVERAGEIF($A$4:$A$20,"L2",S$4:S$20) | E34: =AVERAGEIF($A$4:$A$20,"L3",S$4:S$20) | F34: =AVERAGEIF($A$4:$A$20,"L4",S$4:S$20) | G34: =AVERAGE(B34:F34) | H34: =MIN(B34:F34) | I34: =1-alpha*MAX(0,delta-H34) | J34: =G34*I34 | K34: =1+COUNTIF(bounds,"<"&ROUND(J34,12)) | L34: =AVERAGEIF($A$4:$A$20,"I",S$4:S$20) | M34: =AVERAGEIF($A$4:$A$20,"S",S$4:S$20) | N34: =1+COUNTIF($J$26:$J$35,">"&J34) | O34: ='TOPSIS'!AC13
A35: Україна | B35: =AVERAGEIF($A$4:$A$20,"C",T$4:T$20) | C35: =AVERAGEIF($A$4:$A$20,"L1",T$4:T$20) | D35: =AVERAGEIF($A$4:$A$20,"L2",T$4:T$20) | E35: =AVERAGEIF($A$4:$A$20,"L3",T$4:T$20) | F35: =AVERAGEIF($A$4:$A$20,"L4",T$4:T$20) | G35: =AVERAGE(B35:F35) | H35: =MIN(B35:F35) | I35: =1-alpha*MAX(0,delta-H35) | J35: =G35*I35 | K35: =1+COUNTIF(bounds,"<"&ROUND(J35,12)) | L35: =AVERAGEIF($A$4:$A$20,"I",T$4:T$20) | M35: =AVERAGEIF($A$4:$A$20,"S",T$4:T$20) | N35: =1+COUNTIF($J$26:$J$35,">"&J35) | O35: ='TOPSIS'!AC14
A37: Відповідність твердженню анкети: пряма, прийнятна або проксі (додаткова таблиця S1).
A38: Для деяких пар роки відрізняються (додаткова таблиця S1). ЄС-27 і Німеччина не входять до ранжування.
A39: Строгий набір без слабких проксі та перевірку з вилученням по одному (додаткова таблиця S3) обчислює scripts/statistics_mode_local.py.

Sheet TOPSIS
A1: Ранжування TOPSIS десяти об'єктів таблиці 6 за тими самими п'ятьма шарами, ентропійні ваги
B3: Оцінка шару | H3: Частка p = x / сума стовпця | N3: p * ln p | T3: Зважене нормоване v = w * x / sqrt(sum x^2)
A4: Об'єкт | B4: C | C4: L1 | D4: L2 | E4: L3 | F4: L4 | H4: C | I4: L1 | J4: L2 | K4: L3 | L4: L4 | N4: C | O4: L1 | P4: L2 | Q4: L3 | R4: L4 | T4: C | U4: L1 | V4: L2 | W4: L3 | X4: L4 | Z4: S+ (до ідеалу) | AA4: S- (до антиідеалу) | AB4: Близькість | AC4: Ранг TOPSIS | AD4: Ранг ADMI | AE4: (різниця рангів)^2
A5: Польща | B5: ='Статистичний_режим'!B26 | C5: ='Статистичний_режим'!C26 | D5: ='Статистичний_режим'!D26 | E5: ='Статистичний_режим'!E26 | F5: ='Статистичний_режим'!F26 | H5: =B5/SUM(B$5:B$14) | I5: =C5/SUM(C$5:C$14) | J5: =D5/SUM(D$5:D$14) | K5: =E5/SUM(E$5:E$14) | L5: =F5/SUM(F$5:F$14) | N5: =IF(H5>0,H5*LN(H5),0) | O5: =IF(I5>0,I5*LN(I5),0) | P5: =IF(J5>0,J5*LN(J5),0) | Q5: =IF(K5>0,K5*LN(K5),0) | R5: =IF(L5>0,L5*LN(L5),0) | T5: =B$18*B5/SQRT(SUMPRODUCT(B$5:B$14,B$5:B$14)) | U5: =C$18*C5/SQRT(SUMPRODUCT(C$5:C$14,C$5:C$14)) | V5: =D$18*D5/SQRT(SUMPRODUCT(D$5:D$14,D$5:D$14)) | W5: =E$18*E5/SQRT(SUMPRODUCT(E$5:E$14,E$5:E$14)) | X5: =F$18*F5/SQRT(SUMPRODUCT(F$5:F$14,F$5:F$14)) | Z5: =SQRT((T5-T$19)^2+(U5-U$19)^2+(V5-V$19)^2+(W5-W$19)^2+(X5-X$19)^2) | AA5: =SQRT((T5-T$20)^2+(U5-U$20)^2+(V5-V$20)^2+(W5-W$20)^2+(X5-X$20)^2) | AB5: =AA5/(Z5+AA5) | AC5: =1+COUNTIF($AB$5:$AB$14,">"&AB5) | AD5: ='Статистичний_режим'!N26 | AE5: =(AC5-AD5)^2
A6: Угорщина | B6: ='Статистичний_режим'!B27 | C6: ='Статистичний_режим'!C27 | D6: ='Статистичний_режим'!D27 | E6: ='Статистичний_режим'!E27 | F6: ='Статистичний_режим'!F27 | H6: =B6/SUM(B$5:B$14) | I6: =C6/SUM(C$5:C$14) | J6: =D6/SUM(D$5:D$14) | K6: =E6/SUM(E$5:E$14) | L6: =F6/SUM(F$5:F$14) | N6: =IF(H6>0,H6*LN(H6),0) | O6: =IF(I6>0,I6*LN(I6),0) | P6: =IF(J6>0,J6*LN(J6),0) | Q6: =IF(K6>0,K6*LN(K6),0) | R6: =IF(L6>0,L6*LN(L6),0) | T6: =B$18*B6/SQRT(SUMPRODUCT(B$5:B$14,B$5:B$14)) | U6: =C$18*C6/SQRT(SUMPRODUCT(C$5:C$14,C$5:C$14)) | V6: =D$18*D6/SQRT(SUMPRODUCT(D$5:D$14,D$5:D$14)) | W6: =E$18*E6/SQRT(SUMPRODUCT(E$5:E$14,E$5:E$14)) | X6: =F$18*F6/SQRT(SUMPRODUCT(F$5:F$14,F$5:F$14)) | Z6: =SQRT((T6-T$19)^2+(U6-U$19)^2+(V6-V$19)^2+(W6-W$19)^2+(X6-X$19)^2) | AA6: =SQRT((T6-T$20)^2+(U6-U$20)^2+(V6-V$20)^2+(W6-W$20)^2+(X6-X$20)^2) | AB6: =AA6/(Z6+AA6) | AC6: =1+COUNTIF($AB$5:$AB$14,">"&AB6) | AD6: ='Статистичний_режим'!N27 | AE6: =(AC6-AD6)^2
A7: Румунія | B7: ='Статистичний_режим'!B28 | C7: ='Статистичний_режим'!C28 | D7: ='Статистичний_режим'!D28 | E7: ='Статистичний_режим'!E28 | F7: ='Статистичний_режим'!F28 | H7: =B7/SUM(B$5:B$14) | I7: =C7/SUM(C$5:C$14) | J7: =D7/SUM(D$5:D$14) | K7: =E7/SUM(E$5:E$14) | L7: =F7/SUM(F$5:F$14) | N7: =IF(H7>0,H7*LN(H7),0) | O7: =IF(I7>0,I7*LN(I7),0) | P7: =IF(J7>0,J7*LN(J7),0) | Q7: =IF(K7>0,K7*LN(K7),0) | R7: =IF(L7>0,L7*LN(L7),0) | T7: =B$18*B7/SQRT(SUMPRODUCT(B$5:B$14,B$5:B$14)) | U7: =C$18*C7/SQRT(SUMPRODUCT(C$5:C$14,C$5:C$14)) | V7: =D$18*D7/SQRT(SUMPRODUCT(D$5:D$14,D$5:D$14)) | W7: =E$18*E7/SQRT(SUMPRODUCT(E$5:E$14,E$5:E$14)) | X7: =F$18*F7/SQRT(SUMPRODUCT(F$5:F$14,F$5:F$14)) | Z7: =SQRT((T7-T$19)^2+(U7-U$19)^2+(V7-V$19)^2+(W7-W$19)^2+(X7-X$19)^2) | AA7: =SQRT((T7-T$20)^2+(U7-U$20)^2+(V7-V$20)^2+(W7-W$20)^2+(X7-X$20)^2) | AB7: =AA7/(Z7+AA7) | AC7: =1+COUNTIF($AB$5:$AB$14,">"&AB7) | AD7: ='Статистичний_режим'!N28 | AE7: =(AC7-AD7)^2
A8: Чехія | B8: ='Статистичний_режим'!B29 | C8: ='Статистичний_режим'!C29 | D8: ='Статистичний_режим'!D29 | E8: ='Статистичний_режим'!E29 | F8: ='Статистичний_режим'!F29 | H8: =B8/SUM(B$5:B$14) | I8: =C8/SUM(C$5:C$14) | J8: =D8/SUM(D$5:D$14) | K8: =E8/SUM(E$5:E$14) | L8: =F8/SUM(F$5:F$14) | N8: =IF(H8>0,H8*LN(H8),0) | O8: =IF(I8>0,I8*LN(I8),0) | P8: =IF(J8>0,J8*LN(J8),0) | Q8: =IF(K8>0,K8*LN(K8),0) | R8: =IF(L8>0,L8*LN(L8),0) | T8: =B$18*B8/SQRT(SUMPRODUCT(B$5:B$14,B$5:B$14)) | U8: =C$18*C8/SQRT(SUMPRODUCT(C$5:C$14,C$5:C$14)) | V8: =D$18*D8/SQRT(SUMPRODUCT(D$5:D$14,D$5:D$14)) | W8: =E$18*E8/SQRT(SUMPRODUCT(E$5:E$14,E$5:E$14)) | X8: =F$18*F8/SQRT(SUMPRODUCT(F$5:F$14,F$5:F$14)) | Z8: =SQRT((T8-T$19)^2+(U8-U$19)^2+(V8-V$19)^2+(W8-W$19)^2+(X8-X$19)^2) | AA8: =SQRT((T8-T$20)^2+(U8-U$20)^2+(V8-V$20)^2+(W8-W$20)^2+(X8-X$20)^2) | AB8: =AA8/(Z8+AA8) | AC8: =1+COUNTIF($AB$5:$AB$14,">"&AB8) | AD8: ='Статистичний_режим'!N29 | AE8: =(AC8-AD8)^2
A9: Словаччина | B9: ='Статистичний_режим'!B30 | C9: ='Статистичний_режим'!C30 | D9: ='Статистичний_режим'!D30 | E9: ='Статистичний_режим'!E30 | F9: ='Статистичний_режим'!F30 | H9: =B9/SUM(B$5:B$14) | I9: =C9/SUM(C$5:C$14) | J9: =D9/SUM(D$5:D$14) | K9: =E9/SUM(E$5:E$14) | L9: =F9/SUM(F$5:F$14) | N9: =IF(H9>0,H9*LN(H9),0) | O9: =IF(I9>0,I9*LN(I9),0) | P9: =IF(J9>0,J9*LN(J9),0) | Q9: =IF(K9>0,K9*LN(K9),0) | R9: =IF(L9>0,L9*LN(L9),0) | T9: =B$18*B9/SQRT(SUMPRODUCT(B$5:B$14,B$5:B$14)) | U9: =C$18*C9/SQRT(SUMPRODUCT(C$5:C$14,C$5:C$14)) | V9: =D$18*D9/SQRT(SUMPRODUCT(D$5:D$14,D$5:D$14)) | W9: =E$18*E9/SQRT(SUMPRODUCT(E$5:E$14,E$5:E$14)) | X9: =F$18*F9/SQRT(SUMPRODUCT(F$5:F$14,F$5:F$14)) | Z9: =SQRT((T9-T$19)^2+(U9-U$19)^2+(V9-V$19)^2+(W9-W$19)^2+(X9-X$19)^2) | AA9: =SQRT((T9-T$20)^2+(U9-U$20)^2+(V9-V$20)^2+(W9-W$20)^2+(X9-X$20)^2) | AB9: =AA9/(Z9+AA9) | AC9: =1+COUNTIF($AB$5:$AB$14,">"&AB9) | AD9: ='Статистичний_режим'!N30 | AE9: =(AC9-AD9)^2
A10: Литва | B10: ='Статистичний_режим'!B31 | C10: ='Статистичний_режим'!C31 | D10: ='Статистичний_режим'!D31 | E10: ='Статистичний_режим'!E31 | F10: ='Статистичний_режим'!F31 | H10: =B10/SUM(B$5:B$14) | I10: =C10/SUM(C$5:C$14) | J10: =D10/SUM(D$5:D$14) | K10: =E10/SUM(E$5:E$14) | L10: =F10/SUM(F$5:F$14) | N10: =IF(H10>0,H10*LN(H10),0) | O10: =IF(I10>0,I10*LN(I10),0) | P10: =IF(J10>0,J10*LN(J10),0) | Q10: =IF(K10>0,K10*LN(K10),0) | R10: =IF(L10>0,L10*LN(L10),0) | T10: =B$18*B10/SQRT(SUMPRODUCT(B$5:B$14,B$5:B$14)) | U10: =C$18*C10/SQRT(SUMPRODUCT(C$5:C$14,C$5:C$14)) | V10: =D$18*D10/SQRT(SUMPRODUCT(D$5:D$14,D$5:D$14)) | W10: =E$18*E10/SQRT(SUMPRODUCT(E$5:E$14,E$5:E$14)) | X10: =F$18*F10/SQRT(SUMPRODUCT(F$5:F$14,F$5:F$14)) | Z10: =SQRT((T10-T$19)^2+(U10-U$19)^2+(V10-V$19)^2+(W10-W$19)^2+(X10-X$19)^2) | AA10: =SQRT((T10-T$20)^2+(U10-U$20)^2+(V10-V$20)^2+(W10-W$20)^2+(X10-X$20)^2) | AB10: =AA10/(Z10+AA10) | AC10: =1+COUNTIF($AB$5:$AB$14,">"&AB10) | AD10: ='Статистичний_режим'!N31 | AE10: =(AC10-AD10)^2
A11: Латвія | B11: ='Статистичний_режим'!B32 | C11: ='Статистичний_режим'!C32 | D11: ='Статистичний_режим'!D32 | E11: ='Статистичний_режим'!E32 | F11: ='Статистичний_режим'!F32 | H11: =B11/SUM(B$5:B$14) | I11: =C11/SUM(C$5:C$14) | J11: =D11/SUM(D$5:D$14) | K11: =E11/SUM(E$5:E$14) | L11: =F11/SUM(F$5:F$14) | N11: =IF(H11>0,H11*LN(H11),0) | O11: =IF(I11>0,I11*LN(I11),0) | P11: =IF(J11>0,J11*LN(J11),0) | Q11: =IF(K11>0,K11*LN(K11),0) | R11: =IF(L11>0,L11*LN(L11),0) | T11: =B$18*B11/SQRT(SUMPRODUCT(B$5:B$14,B$5:B$14)) | U11: =C$18*C11/SQRT(SUMPRODUCT(C$5:C$14,C$5:C$14)) | V11: =D$18*D11/SQRT(SUMPRODUCT(D$5:D$14,D$5:D$14)) | W11: =E$18*E11/SQRT(SUMPRODUCT(E$5:E$14,E$5:E$14)) | X11: =F$18*F11/SQRT(SUMPRODUCT(F$5:F$14,F$5:F$14)) | Z11: =SQRT((T11-T$19)^2+(U11-U$19)^2+(V11-V$19)^2+(W11-W$19)^2+(X11-X$19)^2) | AA11: =SQRT((T11-T$20)^2+(U11-U$20)^2+(V11-V$20)^2+(W11-W$20)^2+(X11-X$20)^2) | AB11: =AA11/(Z11+AA11) | AC11: =1+COUNTIF($AB$5:$AB$14,">"&AB11) | AD11: ='Статистичний_режим'!N32 | AE11: =(AC11-AD11)^2
A12: Естонія | B12: ='Статистичний_режим'!B33 | C12: ='Статистичний_режим'!C33 | D12: ='Статистичний_режим'!D33 | E12: ='Статистичний_режим'!E33 | F12: ='Статистичний_режим'!F33 | H12: =B12/SUM(B$5:B$14) | I12: =C12/SUM(C$5:C$14) | J12: =D12/SUM(D$5:D$14) | K12: =E12/SUM(E$5:E$14) | L12: =F12/SUM(F$5:F$14) | N12: =IF(H12>0,H12*LN(H12),0) | O12: =IF(I12>0,I12*LN(I12),0) | P12: =IF(J12>0,J12*LN(J12),0) | Q12: =IF(K12>0,K12*LN(K12),0) | R12: =IF(L12>0,L12*LN(L12),0) | T12: =B$18*B12/SQRT(SUMPRODUCT(B$5:B$14,B$5:B$14)) | U12: =C$18*C12/SQRT(SUMPRODUCT(C$5:C$14,C$5:C$14)) | V12: =D$18*D12/SQRT(SUMPRODUCT(D$5:D$14,D$5:D$14)) | W12: =E$18*E12/SQRT(SUMPRODUCT(E$5:E$14,E$5:E$14)) | X12: =F$18*F12/SQRT(SUMPRODUCT(F$5:F$14,F$5:F$14)) | Z12: =SQRT((T12-T$19)^2+(U12-U$19)^2+(V12-V$19)^2+(W12-W$19)^2+(X12-X$19)^2) | AA12: =SQRT((T12-T$20)^2+(U12-U$20)^2+(V12-V$20)^2+(W12-W$20)^2+(X12-X$20)^2) | AB12: =AA12/(Z12+AA12) | AC12: =1+COUNTIF($AB$5:$AB$14,">"&AB12) | AD12: ='Статистичний_режим'!N33 | AE12: =(AC12-AD12)^2
A13: Болгарія | B13: ='Статистичний_режим'!B34 | C13: ='Статистичний_режим'!C34 | D13: ='Статистичний_режим'!D34 | E13: ='Статистичний_режим'!E34 | F13: ='Статистичний_режим'!F34 | H13: =B13/SUM(B$5:B$14) | I13: =C13/SUM(C$5:C$14) | J13: =D13/SUM(D$5:D$14) | K13: =E13/SUM(E$5:E$14) | L13: =F13/SUM(F$5:F$14) | N13: =IF(H13>0,H13*LN(H13),0) | O13: =IF(I13>0,I13*LN(I13),0) | P13: =IF(J13>0,J13*LN(J13),0) | Q13: =IF(K13>0,K13*LN(K13),0) | R13: =IF(L13>0,L13*LN(L13),0) | T13: =B$18*B13/SQRT(SUMPRODUCT(B$5:B$14,B$5:B$14)) | U13: =C$18*C13/SQRT(SUMPRODUCT(C$5:C$14,C$5:C$14)) | V13: =D$18*D13/SQRT(SUMPRODUCT(D$5:D$14,D$5:D$14)) | W13: =E$18*E13/SQRT(SUMPRODUCT(E$5:E$14,E$5:E$14)) | X13: =F$18*F13/SQRT(SUMPRODUCT(F$5:F$14,F$5:F$14)) | Z13: =SQRT((T13-T$19)^2+(U13-U$19)^2+(V13-V$19)^2+(W13-W$19)^2+(X13-X$19)^2) | AA13: =SQRT((T13-T$20)^2+(U13-U$20)^2+(V13-V$20)^2+(W13-W$20)^2+(X13-X$20)^2) | AB13: =AA13/(Z13+AA13) | AC13: =1+COUNTIF($AB$5:$AB$14,">"&AB13) | AD13: ='Статистичний_режим'!N34 | AE13: =(AC13-AD13)^2
A14: Україна | B14: ='Статистичний_режим'!B35 | C14: ='Статистичний_режим'!C35 | D14: ='Статистичний_режим'!D35 | E14: ='Статистичний_режим'!E35 | F14: ='Статистичний_режим'!F35 | H14: =B14/SUM(B$5:B$14) | I14: =C14/SUM(C$5:C$14) | J14: =D14/SUM(D$5:D$14) | K14: =E14/SUM(E$5:E$14) | L14: =F14/SUM(F$5:F$14) | N14: =IF(H14>0,H14*LN(H14),0) | O14: =IF(I14>0,I14*LN(I14),0) | P14: =IF(J14>0,J14*LN(J14),0) | Q14: =IF(K14>0,K14*LN(K14),0) | R14: =IF(L14>0,L14*LN(L14),0) | T14: =B$18*B14/SQRT(SUMPRODUCT(B$5:B$14,B$5:B$14)) | U14: =C$18*C14/SQRT(SUMPRODUCT(C$5:C$14,C$5:C$14)) | V14: =D$18*D14/SQRT(SUMPRODUCT(D$5:D$14,D$5:D$14)) | W14: =E$18*E14/SQRT(SUMPRODUCT(E$5:E$14,E$5:E$14)) | X14: =F$18*F14/SQRT(SUMPRODUCT(F$5:F$14,F$5:F$14)) | Z14: =SQRT((T14-T$19)^2+(U14-U$19)^2+(V14-V$19)^2+(W14-W$19)^2+(X14-X$19)^2) | AA14: =SQRT((T14-T$20)^2+(U14-U$20)^2+(V14-V$20)^2+(W14-W$20)^2+(X14-X$20)^2) | AB14: =AA14/(Z14+AA14) | AC14: =1+COUNTIF($AB$5:$AB$14,">"&AB14) | AD14: ='Статистичний_режим'!N35 | AE14: =(AC14-AD14)^2
A16: Ентропія e | B16: =-SUM(N5:N14)/LN(10) | C16: =-SUM(O5:O14)/LN(10) | D16: =-SUM(P5:P14)/LN(10) | E16: =-SUM(Q5:Q14)/LN(10) | F16: =-SUM(R5:R14)/LN(10)
A17: Розбіжність 1 - e | B17: =1-B16 | C17: =1-C16 | D17: =1-D16 | E17: =1-E16 | F17: =1-F16
A18: Ентропійна вага w | B18: =B17/SUM($B$17:$F$17) | C18: =C17/SUM($B$17:$F$17) | D18: =D17/SUM($B$17:$F$17) | E18: =E17/SUM($B$17:$F$17) | F18: =F17/SUM($B$17:$F$17)
A19: Ідеал (max v) | T19: =MAX(T5:T14) | U19: =MAX(U5:U14) | V19: =MAX(V5:V14) | W19: =MAX(W5:W14) | X19: =MAX(X5:X14)
A20: Антиідеал (min v) | T20: =MIN(T5:T14) | U20: =MIN(U5:U14) | V20: =MIN(V5:V14) | W20: =MIN(W5:W14) | X20: =MIN(X5:X14)
A22: Рангова кореляція Спірмена ADMI - TOPSIS | B22: =1-6*SUM(AE5:AE14)/(10*(10^2-1))

Sheet Дані_ЄС
A1: Євростат, використання ІКТ на підприємствах: NACE C10-C12, підприємства з 10+ зайнятими, % підприємств
A2: Показник | B2: ERP (E_ERP1) | C2: IOT_PRODUCTION (E_IOTDPP) | D2: ICT_SECURITY_DOCUMENT (E_SECPOL2) | E2: ICT_TRAINING_ICT_SPECIALISTS (E_ITSPT2) | F2: ICT_TRAINING_OTHER_EMPLOYEES (E_ITUST2) | G2: SUPPLY_CHAIN_DATA_EXCHANGE (E_SISC) | H2: DATA_ANALYTICS (E_DA) | I2: IOT_ANY (E_IOT1) | J2: MOBILE_INTERNET (E_EMPMD2_GT0) | K2: PAID_CLOUD (E_CC) | L2: ECOMMERCE_SALES (E_AESELL) | M2: WEBSITE (E_WEB) | N2: CRM (E_CRM1) | O2: EINVOICE_AUTOMATED (E_INV4S_AP) | P2: BI (E_ITBI) | Q2: AI_ANY (E_AI_TANY) | R2: DII_BASIC_V3 (E_DI3_GELO)
A3: Твердження | B3: 1 | C3: 2 | D3: 3 | E3: 5 | F3: 5 | G3: 7 | H3: 8 | I3: 9 | J3: 10 | K3: 11 | L3: 13 | M3: 13 | N3: 14 | O3: 16 | P3: 18 | Q3: 19 | R3: 20
A4: Рік | B4: 2025 | C4: 2021 | D4: 2024 | E4: 2024 | F4: 2024 | G4: 2023 | H4: 2025 | I4: 2021 | J4: 2024 | K4: 2025 | L4: 2025 | M4: 2025 | N4: 2025 | O4: 2023 | P4: 2025 | Q4: 2025 | R4: 2025
A5: Джерело (CSV) | B5: https://ec.europa.eu/eurostat/api/dissemination/sdmx/2.1/data/isoc_eb_iipn2/A.GE10.C10-C12.E_ERP1.PC_ENT.?format=SDMX-CSV | C5: https://ec.europa.eu/eurostat/api/dissemination/sdmx/2.1/data/isoc_eb_iotn2/A.GE10.C10-C12.E_IOTDPP.PC_ENT.?format=SDMX-CSV | D5: https://ec.europa.eu/eurostat/api/dissemination/sdmx/2.1/data/isoc_cisce_ran2/A.GE10.C10-C12.E_SECPOL2.PC_ENT.?format=SDMX-CSV | E5: https://ec.europa.eu/eurostat/api/dissemination/sdmx/2.1/data/isoc_ske_ittn2/A.GE10.C10-C12.E_ITSPT2.PC_ENT.?format=SDMX-CSV | F5: https://ec.europa.eu/eurostat/api/dissemination/sdmx/2.1/data/isoc_ske_ittn2/A.GE10.C10-C12.E_ITUST2.PC_ENT.?format=SDMX-CSV | G5: https://ec.europa.eu/eurostat/api/dissemination/sdmx/2.1/data/isoc_eb_icsn2/A.GE10.C10-C12.E_SISC.PC_ENT.?format=SDMX-CSV | H5: https://ec.europa.eu/eurostat/api/dissemination/sdmx/2.1/data/isoc_eb_dan2/A.GE10.C10-C12.E_DA.PC_ENT.?format=SDMX-CSV | I5: https://ec.europa.eu/eurostat/api/dissemination/sdmx/2.1/data/isoc_eb_iotn2/A.GE10.C10-C12.E_IOT1.PC_ENT.?format=SDMX-CSV | J5: https://ec.europa.eu/eurostat/api/dissemination/sdmx/2.1/data/isoc_cimobe_usen2/A.GE10.C10-C12.E_EMPMD2_GT0.PC_ENT.?format=SDMX-CSV | K5: https://ec.europa.eu/eurostat/api/dissemination/sdmx/2.1/data/isoc_cicce_usen2/A.GE10.C10-C12.E_CC.PC_ENT.?format=SDMX-CSV | L5: https://ec.europa.eu/eurostat/api/dissemination/sdmx/2.1/data/isoc_ec_eseln2/A.GE10.C10-C12.E_AESELL.PC_ENT.?format=SDMX-CSV | M5: https://ec.europa.eu/eurostat/api/dissemination/sdmx/2.1/data/isoc_ciwebn2/A.GE10.C10-C12.E_WEB.PC_ENT.?format=SDMX-CSV | N5: https://ec.europa.eu/eurostat/api/dissemination/sdmx/2.1/data/isoc_eb_iipn2/A.GE10.C10-C12.E_CRM1.PC_ENT.?format=SDMX-CSV | O5: https://ec.europa.eu/eurostat/api/dissemination/sdmx/2.1/data/isoc_eb_icsn2/A.GE10.C10-C12.E_INV4S_AP.PC_ENT.?format=SDMX-CSV | P5: https://ec.europa.eu/eurostat/api/dissemination/sdmx/2.1/data/isoc_eb_iipn2/A.GE10.C10-C12.E_ITBI.PC_ENT.?format=SDMX-CSV | Q5: https://ec.europa.eu/eurostat/api/dissemination/sdmx/2.1/data/isoc_eb_ain2/A.GE10.C10-C12.E_AI_TANY.PC_ENT.?format=SDMX-CSV | R5: https://ec.europa.eu/eurostat/api/dissemination/sdmx/2.1/data/isoc_e_diin2/A.GE10.C10-C12.E_DI3_GELO.PC_ENT.?format=SDMX-CSV
A6: EU27_2020 | B6: 45.06 | C6: 9.68 | D6: 26.68 | E6: 7.1 | F6: 14.36 | G6: 23.16 | H6: 37.73 | I6: 29.43 | J6: 82.47 | K6: 40.88 | L6: 34.16 | M6: 71.83 | N6: 17.99 | O6: 41.5 | P6: 15.22 | Q6: 12.47 | R6: 60.91
A7: AT | B7: 39.48 | C7: 13.7 | D7: 16.94 | E7: 11.97 | F7: 11.14 | G7: 25.73 | H7: 19.32 | K7: 45.99 | L7: 45.69 | M7: 82.38 | N7: 22.4 | O7: 29.09 | P7: 14.79 | Q7: 22.65 | R7: 63.77
A8: BE | E8: 17.83 | F8: 32.41
A9: BG | B9: 20.79 | C9: 5.36 | D9: 5.87 | E9: 2.11 | F9: 3.31 | G9: 10.11 | H9: 22.86 | I9: 15.28 | J9: 72.42 | K9: 11.32 | L9: 14.76 | M9: 45.61 | N9: 6.67 | O9: 19.93 | P9: 6.17 | Q9: 4.72 | R9: 28.38
A10: CY | B10: 51.17 | C10: 15.53 | D10: 23.67 | E10: 7.35 | F10: 19.74 | G10: 8.77 | H10: 47.21 | I10: 43.71 | J10: 87.13 | K10: 47.05 | L10: 24.96 | M10: 60.54 | N10: 23.56 | O10: 19.54 | P10: 23.24 | Q10: 3.61 | R10: 71.74
A11: CZ | B11: 48.16 | C11: 15.03 | D11: 16.8 | E11: 7.5 | F11: 15.92 | G11: 37.12 | H11: 41.51 | I11: 34.29 | J11: 81.73 | K11: 42.58 | L11: 40.98 | M11: 79.11 | N11: 30.18 | O11: 35.18 | P11: 13.49 | Q11: 10.78 | R11: 66.15
A12: DE | B12: 36.76 | C12: 10.5 | D12: 25.81 | E12: 6.39 | F12: 13.32 | G12: 26.65 | H12: 33.79 | I12: 38.22 | J12: 86.34 | K12: 39.13 | L12: 33.04 | M12: 87.9 | N12: 15.17 | O12: 25.93 | P12: 11.64 | Q12: 15.1 | R12: 62.56
A13: DK | C13: 4.82 | D13: 36.4 | E13: 13.25 | F13: 19.46 | G13: 36.49 | I13: 24.38 | M13: 97.47 | N13: 18.31 | O13: 59.51 | P13: 30.85 | Q13: 26.48 | R13: 91.19
A14: EE | B14: 37.23 | C14: 11.98 | D14: 40.14 | E14: 4.53 | F14: 16.59 | G14: 32.43 | H14: 50.27 | I14: 25.37 | J14: 85.59 | K14: 65.76 | L14: 46.96 | M14: 69.47 | N14: 11.41 | O14: 78.38 | P14: 18.33 | Q14: 16.43 | R14: 71.48
A15: EL | B15: 64.7 | C15: 5.78 | D15: 13.84 | E15: 6.84 | F15: 8.35 | G15: 13.83 | H15: 36.33 | I15: 23.44 | J15: 64.55 | K15: 21.58 | L15: 14.51 | M15: 62.49 | N15: 12.65 | O15: 17.63 | P15: 12.22 | Q15: 3.84 | R15: 56.24
A16: ES | B16: 66.42 | D16: 30.13 | E16: 6.37 | F16: 21.08 | H16: 45.34 | J16: 88.83 | K16: 35.36 | L16: 52.06 | M16: 85.84 | N16: 27.11 | P16: 21.96 | Q16: 14.63 | R16: 73.07
A17: FI | R17: 96.43
A18: FR | B18: 44.73 | C18: 2.41 | D18: 14.9 | E18: 3.13 | F18: 7.03 | G18: 19.35 | H18: 31.46 | I18: 20.42 | J18: 79.46 | K18: 25.15 | L18: 33.28 | M18: 57.94 | N18: 15.77 | O18: 32.02 | P18: 11.01 | Q18: 10.75 | R18: 49.63
A19: HR | B19: 16.52 | C19: 3.9 | D19: 9.32 | E19: 3.32 | F19: 11.54 | G19: 5.55 | H19: 33.34 | I19: 22.37 | K19: 29.31 | L19: 18.59 | M19: 37.97 | N19: 8.55 | O19: 55.17 | P19: 7.58 | Q19: 7.27 | R19: 35.65
A20: HU | B20: 28.07 | C20: 6.77 | D20: 8.95 | E20: 5.78 | F20: 9.22 | H20: 42.83 | I20: 21.11 | J20: 70.48 | K20: 33.93 | L20: 26.74 | M20: 58.88 | N20: 12.58 | O20: 31.7 | P20: 5.99 | Q20: 6.05 | R20: 50.96
A21: IE | B21: 40.95 | C21: 11.38 | D21: 65.85 | E21: 18.08 | F21: 33.89 | G21: 35.87 | H21: 48.26 | I21: 40.67 | J21: 89.95 | K21: 71.23 | L21: 60.76 | M21: 82.14 | N21: 17.33 | O21: 55.41 | P21: 27.85 | Q21: 22.66 | R21: 78.91
A22: IT | B22: 48.97 | C22: 21.2 | D22: 30.27 | E22: 6.21 | F22: 15.66 | G22: 15.52 | H22: 50 | I22: 40.33 | K22: 67.77 | L22: 29.37 | M22: 77.49 | N22: 14.78 | O22: 97.92 | P22: 22.03 | Q22: 15.32 | R22: 73.41
A23: LT | B23: 59.21 | C23: 13.88 | D23: 35.41 | E23: 7.73 | F23: 11.97 | G23: 27.11 | H23: 66.58 | I23: 37.8 | J23: 94.02 | K23: 58.23 | L23: 60.44 | M23: 81.57 | N23: 26.04 | O23: 43.99 | P23: 30.71 | Q23: 16.22 | R23: 79.85
A24: LU
A25: LV | B25: 45.3 | C25: 14.43 | D25: 50.69 | E25: 6.16 | F25: 6.63 | G25: 20.34 | H25: 46.34 | I25: 30.05 | J25: 89.96 | K25: 33.37 | L25: 41.87 | M25: 67.79 | N25: 13.14 | O25: 38.2 | P25: 17.96 | Q25: 11.8 | R25: 64.05
A26: MT | B26: 51.12 | C26: 16.37 | D26: 16.51 | E26: 12.92 | F26: 23.69 | G26: 13.18 | H26: 46.72 | I26: 34.88 | J26: 87.43 | K26: 57.71 | L26: 31.23 | M26: 73.75 | N26: 26.29 | O26: 24.71 | P26: 19.22 | Q26: 7.95 | R26: 71.07
A27: NL | B27: 56.49 | C27: 9.17 | D27: 34.67 | E27: 17.3 | F27: 23.72 | G27: 37.45 | H27: 53.28 | I27: 29.12 | J27: 74.41 | K27: 62.97 | L27: 62.2 | M27: 90.77 | N27: 31.25 | O27: 41.55 | P27: 34.8 | Q27: 22.61 | R27: 91.18
A28: PL | B28: 37.18 | C28: 6.4 | D28: 30.78 | E28: 13.48 | F28: 17.33 | G28: 23.63 | H28: 18.72 | I28: 15.84 | J28: 87.56 | K28: 45.08 | L28: 19.19 | M28: 57.15 | N28: 21.14 | O28: 16.13 | P28: 9.96 | Q28: 5.01 | R28: 49.72
A29: PT | C29: 2.28 | D29: 53.98 | E29: 8.14 | F29: 26.75 | G29: 20.25 | I29: 16.76 | J29: 84.66 | K29: 33.02 | N29: 16.85 | O29: 27.08 | P29: 8.38 | Q29: 6.79
A30: RO | B30: 21.02 | C30: 3.04 | D30: 56.74 | E30: 5.75 | F30: 5.59 | G30: 9.78 | H30: 31.63 | I30: 10.11 | J30: 81.61 | K30: 18.73 | L30: 21.05 | M30: 50.19 | N30: 8.78 | O30: 43.09 | P30: 5.93 | Q30: 2.05 | R30: 34.71
A31: SE | B31: 28.82 | C31: 19.37 | D31: 34.96 | E31: 5.46 | F31: 18.39 | G31: 14.93 | H31: 35.44 | I31: 49.89 | K31: 64.58 | L31: 50.49 | M31: 91.5 | N31: 18 | O31: 62.26 | P31: 20.5 | Q31: 21.39 | R31: 81.21
A32: SI | B32: 23.51 | C32: 17.6 | D32: 31.73 | E32: 6.87 | F32: 19.77 | G32: 52.82 | H32: 33.44 | I32: 46.66 | J32: 95.81 | K32: 32.28 | L32: 37.9 | M32: 82.94 | N32: 11.61 | O32: 60.58 | P32: 17.22 | Q32: 17.54 | R32: 49.24
A33: SK | B33: 21.08 | C33: 11.25 | D33: 13.44 | E33: 4.16 | F33: 8.13 | G33: 34.14 | H33: 29.39 | I33: 35.54 | J33: 58.74 | K33: 35.09 | L33: 42.72 | M33: 72.42 | N33: 13.71 | O33: 37.93 | P33: 5.1 | Q33: 10.32 | R33: 53.3
A35: Значення лідера | B35: =MAX(B7:B33) | C35: =MAX(C7:C33) | D35: =MAX(D7:D33) | E35: =MAX(E7:E33) | F35: =MAX(F7:F33) | G35: =MAX(G7:G33) | H35: =MAX(H7:H33) | I35: =MAX(I7:I33) | ... R35: =MAX(R7:R33)
A36: Лідер | B36: =INDEX($A$7:$A$33,MATCH(MAX(B7:B33),B7:B33,0)) | C36: =INDEX($A$7:$A$33,MATCH(MAX(C7:C33),C7:C33,0)) | D36: =INDEX($A$7:$A$33,MATCH(MAX(D7:D33),D7:D33,0)) | E36: =INDEX($A$7:$A$33,MATCH(MAX(E7:E33),E7:E33,0)) | F36: =INDEX($A$7:$A$33,MATCH(MAX(F7:F33),F7:F33,0)) | G36: =INDEX($A$7:$A$33,MATCH(MAX(G7:G33),G7:G33,0)) | H36: =INDEX($A$7:$A$33,MATCH(MAX(H7:H33),H7:H33,0)) | I36: =INDEX($A$7:$A$33,MATCH(MAX(I7:I33),I7:I33,0)) | ... R36: =INDEX($A$7:$A$33,MATCH(MAX(R7:R33),R7:R33,0))
A38: Порожня клітинка = значення не опубліковано (наприклад, позначка u, низька надійність). Лідер = держава-член з найвищим опублікованим значенням. Посилання CSV завантажують повний ряд; фільтруйте за geo і TIME_PERIOD.

Sheet Дані_України
A1: Державна служба статистики України, банк даних stat.gov.ua (SSSU:DF_INFORM_COMMUN_TECH_ENTRP): КВЕД 10-12, підприємства 10+, % підприємств
A3: Показник | B3: Твердження | C3: Ряд Держстату | D3: Рік | E3: Значення, % | F3: Примітка | G3: Пряме завантаження (CSV)
A4: ERP | B4: 1 | C4: SH_ENTRP_ERP_SOFTWARE/_T/_T | D4: 2025 | E4: 20.4 | G4: https://stat.gov.ua/sdmx/workspaces/default:integration/registry/sdmx/3.0/data/dataflow/SSSU/DF_INFORM_COMMUN_TECH_ENTRP/~/SH_ENTRP_ERP_SOFTWARE.UA00000000000000000.*.*._T.C10-C12.A
A5: IOT_PRODUCTION | B5: 2 | C5: SH_ENTRP_INTERNET_THINGS/PURPOSE_INTERNET_THINGS/PRODUCTION_PROCESSES | D5: 2022 | E5: 2.2 | F5: Інформацію сформовано на основі фактично поданих підприємствами звітів і додаткових оцінок показників. | G5: https://stat.gov.ua/sdmx/workspaces/default:integration/registry/sdmx/3.0/data/dataflow/SSSU/DF_INFORM_COMMUN_TECH_ENTRP/~/SH_ENTRP_INTERNET_THINGS.UA00000000000000000.*.*._T.C10-C12.A
A6: ICT_SECURITY_DOCUMENT | B6: 3 | C6: SH_ENTRP_HAVE_DOCUMENT/_T/_T | D6: 2023 | E6: 7.3 | F6: Інформацію сформовано на основі фактично поданих підприємствами звітів і додаткових оцінок показників. | G6: https://stat.gov.ua/sdmx/workspaces/default:integration/registry/sdmx/3.0/data/dataflow/SSSU/DF_INFORM_COMMUN_TECH_ENTRP/~/SH_ENTRP_HAVE_DOCUMENT.UA00000000000000000.*.*._T.C10-C12.A
A7: ICT_TRAINING_ICT_SPECIALISTS | B7: 5 | C7: ISOC_ENT_ICTT2_SH/DIRECTION_STUDY/FOR_ICT | D7: 2025 | E7: 5 | G7: https://stat.gov.ua/sdmx/workspaces/default:integration/registry/sdmx/3.0/data/dataflow/SSSU/DF_INFORM_COMMUN_TECH_ENTRP/~/ISOC_ENT_ICTT2_SH.UA00000000000000000.*.*._T.C10-C12.A
A8: ICT_TRAINING_OTHER_EMPLOYEES | B8: 5 | C8: SH_ENTRP_TRAIN_ICT_OTH/DIRECTION_STUDY/FOR_OTHER | D8: 2025 | E8: 6.5 | F8: джерело ISOC_ENT_ICTT2_SH/DIRECTION_STUDY/FOR_OTHER | G8: https://stat.gov.ua/sdmx/workspaces/default:integration/registry/sdmx/3.0/data/dataflow/SSSU/DF_INFORM_COMMUN_TECH_ENTRP/~/SH_ENTRP_TRAIN_ICT_OTH.UA00000000000000000.*.*._T.C10-C12.A
A9: SUPPLY_CHAIN_DATA_EXCHANGE | B9: 7 | C9: SH_ENTRP_EXCHANG_DATA/_T/_T | D9: 2025 | E9: 31.6 | G9: https://stat.gov.ua/sdmx/workspaces/default:integration/registry/sdmx/3.0/data/dataflow/SSSU/DF_INFORM_COMMUN_TECH_ENTRP/~/SH_ENTRP_EXCHANG_DATA.UA00000000000000000.*.*._T.C10-C12.A
A10: DATA_ANALYTICS | B10: 8 | C10: SH_ENTRP_BIGDATA/_T/_T | D10: 2025 | E10: 21.3 | G10: https://stat.gov.ua/sdmx/workspaces/default:integration/registry/sdmx/3.0/data/dataflow/SSSU/DF_INFORM_COMMUN_TECH_ENTRP/~/SH_ENTRP_BIGDATA.UA00000000000000000.*.*._T.C10-C12.A
A11: IOT_ANY | B11: 9 | C11: SH_ENTRP_INTERNET_THINGS/_T/_T | D11: 2022 | E11: 9.4 | F11: Інформацію сформовано на основі фактично поданих підприємствами звітів і додаткових оцінок показників. | G11: https://stat.gov.ua/sdmx/workspaces/default:integration/registry/sdmx/3.0/data/dataflow/SSSU/DF_INFORM_COMMUN_TECH_ENTRP/~/SH_ENTRP_INTERNET_THINGS.UA00000000000000000.*.*._T.C10-C12.A
A12: MOBILE_INTERNET | B12: 10 | C12: SH_ENTRP_MOBILE_TELEPHONE/_T/_T | D12: 2023 | E12: 45.9 | F12: Інформацію сформовано на основі фактично поданих підприємствами звітів і додаткових оцінок показників. | G12: https://stat.gov.ua/sdmx/workspaces/default:integration/registry/sdmx/3.0/data/dataflow/SSSU/DF_INFORM_COMMUN_TECH_ENTRP/~/SH_ENTRP_MOBILE_TELEPHONE.UA00000000000000000.*.*._T.C10-C12.A
A13: PAID_CLOUD | B13: 11 | C13: SH_ENTRP_CLOUD/CLOUD_COMPUTING_TYPE/_T | D13: 2025 | E13: 16.9 | G13: https://stat.gov.ua/sdmx/workspaces/default:integration/registry/sdmx/3.0/data/dataflow/SSSU/DF_INFORM_COMMUN_TECH_ENTRP/~/SH_ENTRP_CLOUD.UA00000000000000000.*.*._T.C10-C12.A
A14: ECOMMERCE_SALES | B14: 13 | C14: SH_NMBR_ECOMMERCE/_T/_T | D14: 2025 | E14: 16.8 | G14: https://stat.gov.ua/sdmx/workspaces/default:integration/registry/sdmx/3.0/data/dataflow/SSSU/DF_INFORM_COMMUN_TECH_ENTRP/~/SH_NMBR_ECOMMERCE.UA00000000000000000.*.*._T.C10-C12.A
A15: WEBSITE | B15: 13 | C15: SH_ENTRP_WEBSITE/_T/_T | D15: 2025 | E15: 43 | G15: https://stat.gov.ua/sdmx/workspaces/default:integration/registry/sdmx/3.0/data/dataflow/SSSU/DF_INFORM_COMMUN_TECH_ENTRP/~/SH_ENTRP_WEBSITE.UA00000000000000000.*.*._T.C10-C12.A
A16: CRM | B16: 14 | C16: SH_ENTRP_CRM_SOFTWARE/_T/_T | D16: 2025 | E16: 6.9 | G16: https://stat.gov.ua/sdmx/workspaces/default:integration/registry/sdmx/3.0/data/dataflow/SSSU/DF_INFORM_COMMUN_TECH_ENTRP/~/SH_ENTRP_CRM_SOFTWARE.UA00000000000000000.*.*._T.C10-C12.A
A17: EINVOICE_AUTOMATED | B17: 16 | C17: SH_ENTRP_INV/TYPES_ACCOUNTS/ELECTRO_STRUCT_AUTO | D17: 2025 | E17: 37.8 | G17: https://stat.gov.ua/sdmx/workspaces/default:integration/registry/sdmx/3.0/data/dataflow/SSSU/DF_INFORM_COMMUN_TECH_ENTRP/~/SH_ENTRP_INV.UA00000000000000000.*.*._T.C10-C12.A
A18: BI | B18: 18 | C18: SH_ENTRP_BI/_T/_T | D18: 2025 | E18: 6.6 | G18: https://stat.gov.ua/sdmx/workspaces/default:integration/registry/sdmx/3.0/data/dataflow/SSSU/DF_INFORM_COMMUN_TECH_ENTRP/~/SH_ENTRP_BI.UA00000000000000000.*.*._T.C10-C12.A
A19: AI_ANY | B19: 19 | C19: SH_ENTRP_AI_TECHNOLOGIES/_T/_T | D19: 2025 | E19: 5 | G19: https://stat.gov.ua/sdmx/workspaces/default:integration/registry/sdmx/3.0/data/dataflow/SSSU/DF_INFORM_COMMUN_TECH_ENTRP/~/SH_ENTRP_AI_TECHNOLOGIES.UA00000000000000000.*.*._T.C10-C12.A
A20: DII_BASIC_V3 | B20: 20 | C20: SH_ENTRP_BASIC_DIGITAL/_T/_T | D20: 2025 | E20: 27.8 | G20: https://stat.gov.ua/sdmx/workspaces/default:integration/registry/sdmx/3.0/data/dataflow/SSSU/DF_INFORM_COMMUN_TECH_ENTRP/~/SH_ENTRP_BASIC_DIGITAL.UA00000000000000000.*.*._T.C10-C12.A
A22: Кожне посилання завантажує CSV з усіма роками й розрізами (стовпці BREAKDOWN_CATEGORY, BREAKDOWN, TIME_PERIOD, OBS_VALUE). Інтерактивна таблиця: https://stat.gov.ua/uk/explorer?urn=SSSU%3ADF_INFORM_COMMUN_TECH_ENTRP%28~%29

Sheet Діагностичні_ситуації
A1: Таблиця 4. Діагностичні ситуації ADMA (ілюстративні профілі)
A3: Ситуація | B3: DM_C | C3: DM_L1 | D3: DM_L2 | E3: DM_L3 | F3: DM_L4 | G3: DM_I | H3: DM_S | I3: ADMI_base | J3: DM_min | K3: Штраф | L3: ADMI | M3: Рівень за ADMI | N3: Скаляр з DM_I | O3: Рівень за скаляром
A4: Пастка відповідності | B4: 0.7 | C4: 0.4 | D4: 0.45 | E4: 0.05 | F4: 0.6 | G4: 0.3 | H4: 0.4 | I4: =AVERAGE(B4:F4) | J4: =MIN(B4:F4) | K4: =1-alpha*MAX(0,delta-J4) | L4: =I4*K4 | M4: =1+COUNTIF(bounds,"<"&ROUND(L4,12)) | N4: =AVERAGE(B4:G4) | O4: =1+COUNTIF(bounds,"<"&ROUND(N4,12))
A5: Зовнішній тиск ЄС | B5: 0.35 | C5: 0.3 | D5: 0.35 | E5: 0.3 | F5: 0.7 | G5: 0.15 | H5: 0.3 | I5: =AVERAGE(B5:F5) | J5: =MIN(B5:F5) | K5: =1-alpha*MAX(0,delta-J5) | L5: =I5*K5 | M5: =1+COUNTIF(bounds,"<"&ROUND(L5,12)) | N5: =AVERAGE(B5:G5) | O5: =1+COUNTIF(bounds,"<"&ROUND(N5,12))
A6: Обмежувач абсорбційної здатності | B6: 0.55 | C6: 0.1 | D6: 0.45 | E6: 0.45 | F6: 0.5 | G6: 0.35 | H6: 0.4 | I6: =AVERAGE(B6:F6) | J6: =MIN(B6:F6) | K6: =1-alpha*MAX(0,delta-J6) | L6: =I6*K6 | M6: =1+COUNTIF(bounds,"<"&ROUND(L6,12)) | N6: =AVERAGE(B6:G6) | O6: =1+COUNTIF(bounds,"<"&ROUND(N6,12))
A7: Усвідомлена невідповідність | B7: 0.3 | C7: 0.25 | D7: 0.25 | E7: 0.3 | F7: 0.25 | G7: 0.2 | H7: 0.75 | I7: =AVERAGE(B7:F7) | J7: =MIN(B7:F7) | K7: =1-alpha*MAX(0,delta-J7) | L7: =I7*K7 | M7: =1+COUNTIF(bounds,"<"&ROUND(L7,12)) | N7: =AVERAGE(B7:G7) | O7: =1+COUNTIF(bounds,"<"&ROUND(N7,12))
A8: Ілюзія зрілості | B8: 0.55 | C8: 0.55 | D8: 0.55 | E8: 0.55 | F8: 0.55 | G8: 0.15 | H8: 0.5 | I8: =AVERAGE(B8:F8) | J8: =MIN(B8:F8) | K8: =1-alpha*MAX(0,delta-J8) | L8: =I8*K8 | M8: =1+COUNTIF(bounds,"<"&ROUND(L8,12)) | N8: =AVERAGE(B8:G8) | O8: =1+COUNTIF(bounds,"<"&ROUND(N8,12))

Sheet Гранична_смуга
A1: Рівняння (7): рівень знижується через межу b тоді й лише тоді, коли b < ADMI_base <= b / P(DM_min)
A2: Верхню межу також обмежує (4 + DM_min) / 5 - найбільший можливий базовий індекс, коли найслабший шар дорівнює DM_min.
A3: Межа b | B3: DM_min | C3: Штраф P | D3: ADMI_base від | E3: ADMI_base до | F3: Ширина смуги
A4: =INDEX(bounds,1) | B4: 0 | C4: =1-alpha*MAX(0,delta-B4) | D4: =A4 | E4: =MIN(A4/C4,(4+B4)/5) | F4: =MAX(0,E4-A4)
A5: =INDEX(bounds,1) | B5: 0.025 | C5: =1-alpha*MAX(0,delta-B5) | D5: =A5 | E5: =MIN(A5/C5,(4+B5)/5) | F5: =MAX(0,E5-A5)
A6: =INDEX(bounds,1) | B6: 0.05 | C6: =1-alpha*MAX(0,delta-B6) | D6: =A6 | E6: =MIN(A6/C6,(4+B6)/5) | F6: =MAX(0,E6-A6)
A7: =INDEX(bounds,1) | B7: 0.075 | C7: =1-alpha*MAX(0,delta-B7) | D7: =A7 | E7: =MIN(A7/C7,(4+B7)/5) | F7: =MAX(0,E7-A7)
A8: =INDEX(bounds,1) | B8: 0.1 | C8: =1-alpha*MAX(0,delta-B8) | D8: =A8 | E8: =MIN(A8/C8,(4+B8)/5) | F8: =MAX(0,E8-A8)
A9: =INDEX(bounds,1) | B9: 0.125 | C9: =1-alpha*MAX(0,delta-B9) | D9: =A9 | E9: =MIN(A9/C9,(4+B9)/5) | F9: =MAX(0,E9-A9)
A10: =INDEX(bounds,1) | B10: 0.15 | C10: =1-alpha*MAX(0,delta-B10) | D10: =A10 | E10: =MIN(A10/C10,(4+B10)/5) | F10: =MAX(0,E10-A10)
A11: =INDEX(bounds,1) | B11: 0.175 | C11: =1-alpha*MAX(0,delta-B11) | D11: =A11 | E11: =MIN(A11/C11,(4+B11)/5) | F11: =MAX(0,E11-A11)
A12: =INDEX(bounds,1) | B12: 0.2 | C12: =1-alpha*MAX(0,delta-B12) | D12: =A12 | E12: =MIN(A12/C12,(4+B12)/5) | F12: =MAX(0,E12-A12)
A13: =INDEX(bounds,1) | B13: 0.225 | C13: =1-alpha*MAX(0,delta-B13) | D13: =A13 | E13: =MIN(A13/C13,(4+B13)/5) | F13: =MAX(0,E13-A13)
A14: =INDEX(bounds,1) | B14: 0.25 | C14: =1-alpha*MAX(0,delta-B14) | D14: =A14 | E14: =MIN(A14/C14,(4+B14)/5) | F14: =MAX(0,E14-A14)
A15: =INDEX(bounds,1) | B15: 0.275 | C15: =1-alpha*MAX(0,delta-B15) | D15: =A15 | E15: =MIN(A15/C15,(4+B15)/5) | F15: =MAX(0,E15-A15)
... A19: =INDEX(bounds,1) | B19: 0.375 | C19: =1-alpha*MAX(0,delta-B19) | D19: =A19 | E19: =MIN(A19/C19,(4+B19)/5) | F19: =MAX(0,E19-A19)
A20: =INDEX(bounds,2) | B20: 0 | C20: =1-alpha*MAX(0,delta-B20) | D20: =A20 | E20: =MIN(A20/C20,(4+B20)/5) | F20: =MAX(0,E20-A20)
A21: =INDEX(bounds,2) | B21: 0.025 | C21: =1-alpha*MAX(0,delta-B21) | D21: =A21 | E21: =MIN(A21/C21,(4+B21)/5) | F21: =MAX(0,E21-A21)
A22: =INDEX(bounds,2) | B22: 0.05 | C22: =1-alpha*MAX(0,delta-B22) | D22: =A22 | E22: =MIN(A22/C22,(4+B22)/5) | F22: =MAX(0,E22-A22)
A23: =INDEX(bounds,2) | B23: 0.075 | C23: =1-alpha*MAX(0,delta-B23) | D23: =A23 | E23: =MIN(A23/C23,(4+B23)/5) | F23: =MAX(0,E23-A23)
A24: =INDEX(bounds,2) | B24: 0.1 | C24: =1-alpha*MAX(0,delta-B24) | D24: =A24 | E24: =MIN(A24/C24,(4+B24)/5) | F24: =MAX(0,E24-A24)
A25: =INDEX(bounds,2) | B25: 0.125 | C25: =1-alpha*MAX(0,delta-B25) | D25: =A25 | E25: =MIN(A25/C25,(4+B25)/5) | F25: =MAX(0,E25-A25)
A26: =INDEX(bounds,2) | B26: 0.15 | C26: =1-alpha*MAX(0,delta-B26) | D26: =A26 | E26: =MIN(A26/C26,(4+B26)/5) | F26: =MAX(0,E26-A26)
A27: =INDEX(bounds,2) | B27: 0.175 | C27: =1-alpha*MAX(0,delta-B27) | D27: =A27 | E27: =MIN(A27/C27,(4+B27)/5) | F27: =MAX(0,E27-A27)
A28: =INDEX(bounds,2) | B28: 0.2 | C28: =1-alpha*MAX(0,delta-B28) | D28: =A28 | E28: =MIN(A28/C28,(4+B28)/5) | F28: =MAX(0,E28-A28)
A29: =INDEX(bounds,2) | B29: 0.225 | C29: =1-alpha*MAX(0,delta-B29) | D29: =A29 | E29: =MIN(A29/C29,(4+B29)/5) | F29: =MAX(0,E29-A29)
A30: =INDEX(bounds,2) | B30: 0.25 | C30: =1-alpha*MAX(0,delta-B30) | D30: =A30 | E30: =MIN(A30/C30,(4+B30)/5) | F30: =MAX(0,E30-A30)
A31: =INDEX(bounds,2) | B31: 0.275 | C31: =1-alpha*MAX(0,delta-B31) | D31: =A31 | E31: =MIN(A31/C31,(4+B31)/5) | F31: =MAX(0,E31-A31)
... A35: =INDEX(bounds,2) | B35: 0.375 | C35: =1-alpha*MAX(0,delta-B35) | D35: =A35 | E35: =MIN(A35/C35,(4+B35)/5) | F35: =MAX(0,E35-A35)
A36: =INDEX(bounds,3) | B36: 0 | C36: =1-alpha*MAX(0,delta-B36) | D36: =A36 | E36: =MIN(A36/C36,(4+B36)/5) | F36: =MAX(0,E36-A36)
A37: =INDEX(bounds,3) | B37: 0.025 | C37: =1-alpha*MAX(0,delta-B37) | D37: =A37 | E37: =MIN(A37/C37,(4+B37)/5) | F37: =MAX(0,E37-A37)
A38: =INDEX(bounds,3) | B38: 0.05 | C38: =1-alpha*MAX(0,delta-B38) | D38: =A38 | E38: =MIN(A38/C38,(4+B38)/5) | F38: =MAX(0,E38-A38)
A39: =INDEX(bounds,3) | B39: 0.075 | C39: =1-alpha*MAX(0,delta-B39) | D39: =A39 | E39: =MIN(A39/C39,(4+B39)/5) | F39: =MAX(0,E39-A39)
A40: =INDEX(bounds,3) | B40: 0.1 | C40: =1-alpha*MAX(0,delta-B40) | D40: =A40 | E40: =MIN(A40/C40,(4+B40)/5) | F40: =MAX(0,E40-A40)
A41: =INDEX(bounds,3) | B41: 0.125 | C41: =1-alpha*MAX(0,delta-B41) | D41: =A41 | E41: =MIN(A41/C41,(4+B41)/5) | F41: =MAX(0,E41-A41)
A42: =INDEX(bounds,3) | B42: 0.15 | C42: =1-alpha*MAX(0,delta-B42) | D42: =A42 | E42: =MIN(A42/C42,(4+B42)/5) | F42: =MAX(0,E42-A42)
A43: =INDEX(bounds,3) | B43: 0.175 | C43: =1-alpha*MAX(0,delta-B43) | D43: =A43 | E43: =MIN(A43/C43,(4+B43)/5) | F43: =MAX(0,E43-A43)
A44: =INDEX(bounds,3) | B44: 0.2 | C44: =1-alpha*MAX(0,delta-B44) | D44: =A44 | E44: =MIN(A44/C44,(4+B44)/5) | F44: =MAX(0,E44-A44)
