Workbook
Name alpha: Parameters!$B$3
Name delta: Parameters!$B$4
Name bounds: Parameters!$B$7:$B$10

Sheet README
A1: ADMA workbook: hand-checkable calculations of the paper
A3: Every number on the calculation sheets is an Excel formula. Yellow cells are inputs you may change; blue cells are values copied from official sources (each with its link). Changing the yellow cells on Parameters recalculates every sheet.
A5: Sheets and the paper
A6: Parameters: alpha, delta and level bounds used by all formulas (Section 3.3, Table 2).
A7: Calculator: enter 19 questionnaire answers (1-5) and get layer scores, penalty, ADMI, level, DM_I, DM_S (equations 1-5).
A8: Worked_example: the profile of Section 4.1.
A9: Statistics_mode: Table 7 (equation 6). Uses EU_data and UA_data.
A10: EU_data: Eurostat values for all EU-27 countries; the leader is found with MAX/INDEX/MATCH.
A11: UA_data: Derzhstat values with direct download links.
A12: Diagnostic_situations: Table 6.
A13: Boundary_band: equation (7), the band of base index values in which the penalty changes the level (Section 4.2).
A14: Experiment_sample: the first 1 000 of the 100 000 generated profiles (uniform scenario) with all formulas row by row, and the corresponding results of the full run for comparison.
... A28: The workbook is generated by scripts/build_workbook.py from data/raw and data/generated; this README is generated together with the README sheet and has the same content.

Sheet Parameters
A1: Parameters
A3: alpha | B3: 0.4 | C3: Strength of the weak-link penalty (calibrated value)
A4: delta | B4: 0.375 | C4: Threshold of critical layer weakness (calibrated value; 0.375 = mean answer 2.5)
A6: Level bounds (Table 2)
A7: Level 1 | 2 | B7: 0.2
A8: Level 2 | 3 | B8: 0.4
A9: Level 3 | 4 | B9: 0.6
A10: Level 4 | 5 | B10: 0.8
A12: Initial values before calibration: alpha = 0.50, delta = 0.25. Model-adjusted bounds used as a robustness check: 0.25, 0.45, 0.60, 0.80.

Sheet Calculator
A1: ADMI calculator: enter answers 1-5 in the yellow cells
A3: # | B3: Block | C3: Statement | D3: Answer (1-5) | E3: Normalised (eq. 1)
A4: 1 | B4: C | C4: Software for production and resource planning (ERP, MES) | D4: 3 | E4: =(D4-1)/4
A5: 2 | B5: C | C5: Automation of production processes with digital equipment | D5: 3 | E5: =(D5-1)/4
A6: 3 | B6: C | C6: Approved digital development strategy or plan for 2-3 years | D6: 4 | E6: =(D6-1)/4
A7: 4 | B7: L1 | C7: Digital tools for human resource management (HRM) | D7: 3 | E7: =(D7-1)/4
A8: 5 | B8: L1 | C8: Employees have the skills to work with digital tools | D8: 3 | E8: =(D8-1)/4
A9: 6 | B9: L2 | C9: Digital accounting of inventories (WMS or spreadsheets) | D9: 3 | E9: =(D9-1)/4
A10: 7 | B10: L2 | C10: Collection and analysis of data on resource use, deviations and losses | D10: 3 | E10: =(D10-1)/4
A11: 8 | B11: L2 | C11: Monitoring of storage conditions with sensors or IoT | D11: 3 | E11: =(D11-1)/4
A12: 9 | B12: L3 | C12: GPS monitoring or telematics on vehicles and machinery | D12: 2 | E12: =(D12-1)/4
A13: 10 | B13: L3 | C13: Data-based maintenance planning (CMMS) | D13: 1 | E13: =(D13-1)/4
A14: 11 | B14: L3 | C14: Precision farming or precision livestock technologies | D14: 1 | E14: =(D14-1)/4
A15: 12 | B15: L4 | C15: Digital sales channels (website, e-commerce, EDI) | D15: 3 | E15: =(D15-1)/4
... A22: 19 | B22: S | C22: Dedicated budget or resources for digitalisation | D22: 2 | E22: =(D22-1)/4
C24: Result
C25: DM_C (eq. 2) | D25: =AVERAGE(E4:E6)
C26: DM_L1 (eq. 2) | D26: =AVERAGE(E7:E8)
C27: DM_L2 (eq. 2) | D27: =AVERAGE(E9:E11)
C28: DM_L3 (eq. 2) | D28: =AVERAGE(E12:E14)
C29: DM_L4 (eq. 2) | D29: =AVERAGE(E15:E17)
C30: DM_I (integration, outside the index) | D30: =AVERAGE(E18:E20)
C31: DM_S (strategy, outside the index) | D31: =AVERAGE(E21:E22)
C32: ADMI_base (eq. 3) | D32: =AVERAGE(D25:D29)
C33: DM_min | D33: =MIN(D25:D29)
C34: Penalty P (eq. 4) | D34: =1-alpha*MAX(0,delta-D33)
C35: ADMI (eq. 5) | D35: =D32*D34
C36: Level by ADMI_base | D36: =1+COUNTIF(bounds,"<"&ROUND(D32,12))
C37: Level by ADMI | D37: =1+COUNTIF(bounds,"<"&ROUND(D35,12))
C38: Penalty changed the level? | D38: =IF(D36<>D37,"yes","no")

Sheet Worked_example
A1: Section 4.1: worked example (ADMI_base 0.433, level 3 -> ADMI 0.383, level 2)
A3: # | B3: Block | C3: Statement | D3: Answer (1-5) | E3: Normalised (eq. 1)
A4: 1 | B4: C | C4: Software for production and resource planning (ERP, MES) | D4: 3 | E4: =(D4-1)/4
A5: 2 | B5: C | C5: Automation of production processes with digital equipment | D5: 3 | E5: =(D5-1)/4
A6: 3 | B6: C | C6: Approved digital development strategy or plan for 2-3 years | D6: 4 | E6: =(D6-1)/4
A7: 4 | B7: L1 | C7: Digital tools for human resource management (HRM) | D7: 3 | E7: =(D7-1)/4
A8: 5 | B8: L1 | C8: Employees have the skills to work with digital tools | D8: 3 | E8: =(D8-1)/4
A9: 6 | B9: L2 | C9: Digital accounting of inventories (WMS or spreadsheets) | D9: 3 | E9: =(D9-1)/4
A10: 7 | B10: L2 | C10: Collection and analysis of data on resource use, deviations and losses | D10: 3 | E10: =(D10-1)/4
A11: 8 | B11: L2 | C11: Monitoring of storage conditions with sensors or IoT | D11: 3 | E11: =(D11-1)/4
A12: 9 | B12: L3 | C12: GPS monitoring or telematics on vehicles and machinery | D12: 2 | E12: =(D12-1)/4
A13: 10 | B13: L3 | C13: Data-based maintenance planning (CMMS) | D13: 1 | E13: =(D13-1)/4
A14: 11 | B14: L3 | C14: Precision farming or precision livestock technologies | D14: 1 | E14: =(D14-1)/4
A15: 12 | B15: L4 | C15: Digital sales channels (website, e-commerce, EDI) | D15: 3 | E15: =(D15-1)/4
... A22: 19 | B22: S | C22: Dedicated budget or resources for digitalisation | D22: 2 | E22: =(D22-1)/4
C24: Result
C25: DM_C (eq. 2) | D25: =AVERAGE(E4:E6)
C26: DM_L1 (eq. 2) | D26: =AVERAGE(E7:E8)
C27: DM_L2 (eq. 2) | D27: =AVERAGE(E9:E11)
C28: DM_L3 (eq. 2) | D28: =AVERAGE(E12:E14)
C29: DM_L4 (eq. 2) | D29: =AVERAGE(E15:E17)
C30: DM_I (integration, outside the index) | D30: =AVERAGE(E18:E20)
C31: DM_S (strategy, outside the index) | D31: =AVERAGE(E21:E22)
C32: ADMI_base (eq. 3) | D32: =AVERAGE(D25:D29)
C33: DM_min | D33: =MIN(D25:D29)
C34: Penalty P (eq. 4) | D34: =1-alpha*MAX(0,delta-D33)
C35: ADMI (eq. 5) | D35: =D32*D34
C36: Level by ADMI_base | D36: =1+COUNTIF(bounds,"<"&ROUND(D32,12))
C37: Level by ADMI | D37: =1+COUNTIF(bounds,"<"&ROUND(D35,12))
C38: Penalty changed the level? | D38: =IF(D36<>D37,"yes","no")

Sheet Statistics_mode
A1: Table 7. Statistics mode of ADMA for the Ukrainian food-processing industry (equation 6, P_min = 0)
A3: Layer | B3: Indicator | C3: Statement | D3: Ukraine, % | E3: Ukraine year | F3: EU27, % | G3: EU year | H3: Leader | I3: Leader, % | J3: DM Ukraine | K3: DM EU27
A4: C | B4: ERP software | C4: 1 | D4: =UA_data!$D$4 | E4: 2025 | F4: =EU_data!$B$4 | G4: 2025 | H4: =INDEX(EU_data!$A$5:$A$31,MATCH(MAX(EU_data!$B$5:$B$31),EU_data!$B$5:$B$31,0)) | I4: =MAX(EU_data!$B$5:$B$31) | J4: =D4/I4 | K4: =F4/I4
A5: C | B5: IoT for production processes | C5: 2 | D5: =UA_data!$D$5 | E5: 2022 | F5: =EU_data!$C$4 | G5: 2021 | H5: =INDEX(EU_data!$A$5:$A$31,MATCH(MAX(EU_data!$C$5:$C$31),EU_data!$C$5:$C$31,0)) | I5: =MAX(EU_data!$C$5:$C$31) | J5: =D5/I5 | K5: =F5/I5
A6: C | B6: Document(s) on ICT security | C6: 3 | D6: =UA_data!$D$6 | E6: 2023 | F6: =EU_data!$D$4 | G6: 2024 | H6: =INDEX(EU_data!$A$5:$A$31,MATCH(MAX(EU_data!$D$5:$D$31),EU_data!$D$5:$D$31,0)) | I6: =MAX(EU_data!$D$5:$D$31) | J6: =D6/I6 | K6: =F6/I6
A7: L2 | B7: Internet of Things | C7: 8 | D7: =UA_data!$D$7 | E7: 2022 | F7: =EU_data!$E$4 | G7: 2021 | H7: =INDEX(EU_data!$A$5:$A$31,MATCH(MAX(EU_data!$E$5:$E$31),EU_data!$E$5:$E$31,0)) | I7: =MAX(EU_data!$E$5:$E$31) | J7: =D7/I7 | K7: =F7/I7
A8: L3 | B8: Paid cloud computing services | C8: 10 | D8: =UA_data!$D$8 | E8: 2025 | F8: =EU_data!$F$4 | G8: 2025 | H8: =INDEX(EU_data!$A$5:$A$31,MATCH(MAX(EU_data!$F$5:$F$31),EU_data!$F$5:$F$31,0)) | I8: =MAX(EU_data!$F$5:$F$31) | J8: =D8/I8 | K8: =F8/I8
A9: L4 | B9: CRM software | C9: 13 | D9: =UA_data!$D$9 | E9: 2025 | F9: =EU_data!$G$4 | G9: 2025 | H9: =INDEX(EU_data!$A$5:$A$31,MATCH(MAX(EU_data!$G$5:$G$31),EU_data!$G$5:$G$31,0)) | I9: =MAX(EU_data!$G$5:$G$31) | J9: =D9/I9 | K9: =F9/I9
A11: Layer profile (mean of the layer's indicators)
A12: Layer | B12: DM Ukraine | C12: DM EU27 | D12: Ukraine below delta? | E12: EU27 below delta?
A13: C | B13: =AVERAGEIF($A$4:$A$9,A13,$J$4:$J$9) | C13: =AVERAGEIF($A$4:$A$9,A13,$K$4:$K$9) | D13: =IF(B13<delta,"yes","no") | E13: =IF(C13<delta,"yes","no")
A14: L2 | B14: =AVERAGEIF($A$4:$A$9,A14,$J$4:$J$9) | C14: =AVERAGEIF($A$4:$A$9,A14,$K$4:$K$9) | D14: =IF(B14<delta,"yes","no") | E14: =IF(C14<delta,"yes","no")
A15: L3 | B15: =AVERAGEIF($A$4:$A$9,A15,$J$4:$J$9) | C15: =AVERAGEIF($A$4:$A$9,A15,$K$4:$K$9) | D15: =IF(B15<delta,"yes","no") | E15: =IF(C15<delta,"yes","no")
A16: L4 | B16: =AVERAGEIF($A$4:$A$9,A16,$J$4:$J$9) | C16: =AVERAGEIF($A$4:$A$9,A16,$K$4:$K$9) | D16: =IF(B16<delta,"yes","no") | E16: =IF(C16<delta,"yes","no")
A18: L1 (human capital) has no common indicator in the two surveys, so the full ADMI cannot be computed in the statistics mode.
A19: Years differ for three indicators (Section 3.6 of the paper): ICT security documents UA 2023 / EU 2024; IoT UA 2022 / EU 2021.
A20: Leader = EU-27 country with the highest published value; BE, FI and LU publish no values for C10-C12.

Sheet EU_data
A1: Eurostat, ICT usage in enterprises: NACE C10-C12, enterprises with 10+ persons employed, % of enterprises
A2: Country | B2: E_ERP1 2025 | C2: E_IOTDPP 2021 | D2: E_SECPOL2 2024 | E2: E_IOT1 2021 | F2: E_CC 2025 | G2: E_CRM1 2025
A3: Source (CSV) | B3: https://ec.europa.eu/eurostat/api/dissemination/sdmx/2.1/data/isoc_eb_iipn2/A.GE10.C10-C12+C10-S951_X_K.E_ERP1+E_CRM1.PC_ENT.?format=SDMX-CSV | C3: https://ec.europa.eu/eurostat/api/dissemination/sdmx/2.1/data/isoc_eb_iotn2/A.GE10.C10-C12+C10-S951_X_K.E_IOT1+E_IOTDPP.PC_ENT.?format=SDMX-CSV | D3: https://ec.europa.eu/eurostat/api/dissemination/sdmx/2.1/data/isoc_cisce_ran2/A.GE10.C10-C12+C10-S951_X_K.E_SECMGE1+E_SECPOL2.PC_ENT.?format=SDMX-CSV | E3: https://ec.europa.eu/eurostat/api/dissemination/sdmx/2.1/data/isoc_eb_iotn2/A.GE10.C10-C12+C10-S951_X_K.E_IOT1+E_IOTDPP.PC_ENT.?format=SDMX-CSV | F3: https://ec.europa.eu/eurostat/api/dissemination/sdmx/2.1/data/isoc_cicce_usen2/A.GE10.C10-C12+C10-S951_X_K.E_CC+E_CC1_S.PC_ENT.?format=SDMX-CSV | G3: https://ec.europa.eu/eurostat/api/dissemination/sdmx/2.1/data/isoc_eb_iipn2/A.GE10.C10-C12+C10-S951_X_K.E_ERP1+E_CRM1.PC_ENT.?format=SDMX-CSV
A4: EU27_2020 | B4: 45.06 | C4: 9.68 | D4: 26.68 | E4: 29.43 | F4: 40.88 | G4: 17.99
A5: AT | B5: 39.48 | C5: 13.7 | D5: 16.94 | F5: 45.99 | G5: 22.4
A6: BE
A7: BG | B7: 20.79 | C7: 5.36 | D7: 5.87 | E7: 15.28 | F7: 11.32 | G7: 6.67
A8: CY | B8: 51.17 | C8: 15.53 | D8: 23.67 | E8: 43.71 | F8: 47.05 | G8: 23.56
A9: CZ | B9: 48.16 | C9: 15.03 | D9: 16.8 | E9: 34.29 | F9: 42.58 | G9: 30.18
A10: DE | B10: 36.76 | C10: 10.5 | D10: 25.81 | E10: 38.22 | F10: 39.13 | G10: 15.17
A11: DK | C11: 4.82 | D11: 36.4 | E11: 24.38 | G11: 18.31
A12: EE | B12: 37.23 | C12: 11.98 | D12: 40.14 | E12: 25.37 | F12: 65.76 | G12: 11.41
A13: EL | B13: 64.7 | C13: 5.78 | D13: 13.84 | E13: 23.44 | F13: 21.58 | G13: 12.65
A14: ES | B14: 66.42 | D14: 30.13 | F14: 35.36 | G14: 27.11
A15: FI
A16: FR | B16: 44.73 | C16: 2.41 | D16: 14.9 | E16: 20.42 | F16: 25.15 | G16: 15.77
A17: HR | B17: 16.52 | C17: 3.9 | D17: 9.32 | E17: 22.37 | F17: 29.31 | G17: 8.55
A18: HU | B18: 28.07 | C18: 6.77 | D18: 8.95 | E18: 21.11 | F18: 33.93 | G18: 12.58
A19: IE | B19: 40.95 | C19: 11.38 | D19: 65.85 | E19: 40.67 | F19: 71.23 | G19: 17.33
A20: IT | B20: 48.97 | C20: 21.2 | D20: 30.27 | E20: 40.33 | F20: 67.77 | G20: 14.78
A21: LT | B21: 59.21 | C21: 13.88 | D21: 35.41 | E21: 37.8 | F21: 58.23 | G21: 26.04
A22: LU
A23: LV | B23: 45.3 | C23: 14.43 | D23: 50.69 | E23: 30.05 | F23: 33.37 | G23: 13.14
A24: MT | B24: 51.12 | C24: 16.37 | D24: 16.51 | E24: 34.88 | F24: 57.71 | G24: 26.29
A25: NL | B25: 56.49 | C25: 9.17 | D25: 34.67 | E25: 29.12 | F25: 62.97 | G25: 31.25
A26: PL | B26: 37.18 | C26: 6.4 | D26: 30.78 | E26: 15.84 | F26: 45.08 | G26: 21.14
A27: PT | C27: 2.28 | D27: 53.98 | E27: 16.76 | F27: 33.02 | G27: 16.85
A28: RO | B28: 21.02 | C28: 3.04 | D28: 56.74 | E28: 10.11 | F28: 18.73 | G28: 8.78
A29: SE | B29: 28.82 | C29: 19.37 | D29: 34.96 | E29: 49.89 | F29: 64.58 | G29: 18
A30: SI | B30: 23.51 | C30: 17.6 | D30: 31.73 | E30: 46.66 | F30: 32.28 | G30: 11.61
A31: SK | B31: 21.08 | C31: 11.25 | D31: 13.44 | E31: 35.54 | F31: 35.09 | G31: 13.71
A33: Empty cell = no published value (flag u, low reliability). The CSV links download the full series; filter by indic_is, geo and TIME_PERIOD.

Sheet UA_data
A1: State Statistics Service of Ukraine, data bank stat.gov.ua (SSSU:DF_INFORM_COMMUN_TECH_ENTRP): KVED 10-12, % of enterprises
A3: Indicator | B3: Breakdown | C3: Year | D3: Value, % | E3: Data updated | F3: Direct download (CSV)
A4: ERP software | B4: _T / _T | C4: 2025 | D4: 20.4 | E4: 16.09.2026 | F4: https://stat.gov.ua/sdmx/workspaces/default:integration/registry/sdmx/3.0/data/dataflow/SSSU/DF_INFORM_COMMUN_TECH_ENTRP/~/SH_ENTRP_ERP_SOFTWARE.UA00000000000000000._T._T._T.C10-C12+_T.A
A5: IoT for production processes | B5: PURPOSE_INTERNET_THINGS / PRODUCTION_PROCESSES | C5: 2022 | D5: 2.2 | E5: 16.09.2026 | F5: https://stat.gov.ua/sdmx/workspaces/default:integration/registry/sdmx/3.0/data/dataflow/SSSU/DF_INFORM_COMMUN_TECH_ENTRP/~/SH_ENTRP_INTERNET_THINGS.UA00000000000000000.*.*._T.C10-C12+_T.A
A6: Document(s) on ICT security | B6: _T / _T | C6: 2023 | D6: 7.3 | E6: 16.09.2026 | F6: https://stat.gov.ua/sdmx/workspaces/default:integration/registry/sdmx/3.0/data/dataflow/SSSU/DF_INFORM_COMMUN_TECH_ENTRP/~/SH_ENTRP_HAVE_DOCUMENT.UA00000000000000000._T._T._T.C10-C12+_T.A
A7: Internet of Things | B7: _T / _T | C7: 2022 | D7: 9.4 | E7: 16.09.2026 | F7: https://stat.gov.ua/sdmx/workspaces/default:integration/registry/sdmx/3.0/data/dataflow/SSSU/DF_INFORM_COMMUN_TECH_ENTRP/~/SH_ENTRP_INTERNET_THINGS.UA00000000000000000.*.*._T.C10-C12+_T.A
A8: Paid cloud computing services | B8: CLOUD_COMPUTING_TYPE / _T | C8: 2025 | D8: 16.9 | E8: 16.09.2026 | F8: https://stat.gov.ua/sdmx/workspaces/default:integration/registry/sdmx/3.0/data/dataflow/SSSU/DF_INFORM_COMMUN_TECH_ENTRP/~/SH_ENTRP_CLOUD.UA00000000000000000.CLOUD_COMPUTING_TYPE+_T._T._T.C10-C12+_T.A
A9: CRM software | B9: _T / _T | C9: 2025 | D9: 6.9 | E9: 16.09.2026 | F9: https://stat.gov.ua/sdmx/workspaces/default:integration/registry/sdmx/3.0/data/dataflow/SSSU/DF_INFORM_COMMUN_TECH_ENTRP/~/SH_ENTRP_CRM_SOFTWARE.UA00000000000000000._T._T._T.C10-C12+_T.A
A11: Each link downloads a CSV with all years (columns TIME_PERIOD, OBS_VALUE). Interactive table: https://stat.gov.ua/uk/explorer?urn=SSSU%3ADF_INFORM_COMMUN_TECH_ENTRP%28~%29

Sheet Diagnostic_situations
A1: Table 6. Diagnostic situations of ADMA (illustrative profiles)
A3: Situation | B3: DM_C | C3: DM_L1 | D3: DM_L2 | E3: DM_L3 | F3: DM_L4 | G3: DM_I | H3: DM_S | I3: ADMI_base | J3: DM_min | K3: Penalty | L3: ADMI | M3: Level by ADMI | N3: Scalar incl. DM_I | O3: Level by scalar
A4: Compliance trap | B4: 0.7 | C4: 0.4 | D4: 0.45 | E4: 0.05 | F4: 0.6 | G4: 0.3 | H4: 0.4 | I4: =AVERAGE(B4:F4) | J4: =MIN(B4:F4) | K4: =1-alpha*MAX(0,delta-J4) | L4: =I4*K4 | M4: =1+COUNTIF(bounds,"<"&ROUND(L4,12)) | N4: =AVERAGE(B4:G4) | O4: =1+COUNTIF(bounds,"<"&ROUND(N4,12))
A5: External EU pressure | B5: 0.35 | C5: 0.3 | D5: 0.35 | E5: 0.3 | F5: 0.7 | G5: 0.15 | H5: 0.3 | I5: =AVERAGE(B5:F5) | J5: =MIN(B5:F5) | K5: =1-alpha*MAX(0,delta-J5) | L5: =I5*K5 | M5: =1+COUNTIF(bounds,"<"&ROUND(L5,12)) | N5: =AVERAGE(B5:G5) | O5: =1+COUNTIF(bounds,"<"&ROUND(N5,12))
A6: Absorptive limiter | B6: 0.55 | C6: 0.1 | D6: 0.45 | E6: 0.45 | F6: 0.5 | G6: 0.35 | H6: 0.4 | I6: =AVERAGE(B6:F6) | J6: =MIN(B6:F6) | K6: =1-alpha*MAX(0,delta-J6) | L6: =I6*K6 | M6: =1+COUNTIF(bounds,"<"&ROUND(L6,12)) | N6: =AVERAGE(B6:G6) | O6: =1+COUNTIF(bounds,"<"&ROUND(N6,12))
A7: Aware mismatch | B7: 0.3 | C7: 0.25 | D7: 0.25 | E7: 0.3 | F7: 0.25 | G7: 0.2 | H7: 0.75 | I7: =AVERAGE(B7:F7) | J7: =MIN(B7:F7) | K7: =1-alpha*MAX(0,delta-J7) | L7: =I7*K7 | M7: =1+COUNTIF(bounds,"<"&ROUND(L7,12)) | N7: =AVERAGE(B7:G7) | O7: =1+COUNTIF(bounds,"<"&ROUND(N7,12))
A8: Illusion of maturity | B8: 0.55 | C8: 0.55 | D8: 0.55 | E8: 0.55 | F8: 0.55 | G8: 0.15 | H8: 0.5 | I8: =AVERAGE(B8:F8) | J8: =MIN(B8:F8) | K8: =1-alpha*MAX(0,delta-J8) | L8: =I8*K8 | M8: =1+COUNTIF(bounds,"<"&ROUND(L8,12)) | N8: =AVERAGE(B8:G8) | O8: =1+COUNTIF(bounds,"<"&ROUND(N8,12))

Sheet Boundary_band
A1: Equation (7): the level drops across bound b if and only if b < ADMI_base <= b / P(DM_min)
A2: Upper limit is also capped by (4 + DM_min) / 5, the largest base index possible when the weakest layer equals DM_min.
A3: Bound b | B3: DM_min | C3: Penalty P | D3: ADMI_base from | E3: ADMI_base to | F3: Band width
A4: =INDEX(bounds,1) | B4: 0 | C4: =1-alpha*MAX(0,delta-B4) | D4: =A4 | E4: =MIN(A4/C4,(4+B4)/5) | F4: =MAX(0,E4-A4)
A5: =INDEX(bounds,1) | B5: 0.025 | C5: =1-alpha*MAX(0,delta-B5) | D5: =A5 | E5: =MIN(A5/C5,(4+B5)/5) | F5: =MAX(0,E5-A5)
A6: =INDEX(bounds,1) | B6: 0.05 | C6: =1-alpha*MAX(0,delta-B6) | D6: =A6 | E6: =MIN(A6/C6,(4+B6)/5) | F6: =MAX(0,E6-A6)
A7: =INDEX(bounds,1) | B7: 0.075 | C7: =1-alpha*MAX(0,delta-B7) | D7: =A7 | E7: =MIN(A7/C7,(4+B7)/5) | F7: =MAX(0,E7-A7)
A8: =INDEX(bounds,1) | B8: 0.1 | C8: =1-alpha*MAX(0,delta-B8) | D8: =A8 | E8: =MIN(A8/C8,(4+B8)/5) | F8: =MAX(0,E8-A8)
A9: =INDEX(bounds,1) | B9: 0.125 | C9: =1-alpha*MAX(0,delta-B9) | D9: =A9 | E9: =MIN(A9/C9,(4+B9)/5) | F9: =MAX(0,E9-A9)
A10: =INDEX(bounds,1) | B10: 0.15 | C10: =1-alpha*MAX(0,delta-B10) | D10: =A10 | E10: =MIN(A10/C10,(4+B10)/5) | F10: =MAX(0,E10-A10)
A11: =INDEX(bounds,1) | B11: 0.175 | C11: =1-alpha*MAX(0,delta-B11) | D11: =A11 | E11: =MIN(A11/C11,(4+B11)/5) | F11: =MAX(0,E11-A11)
A12: =INDEX(bounds,1) | B12: 0.2 | C12: =1-alpha*MAX(0,delta-B12) | D12: =A12 | E12: =MIN(A12/C12,(4+B12)/5) | F12: =MAX(0,E12-A12)
A13: =INDEX(bounds,1) | B13: 0.225 | C13: =1-alpha*MAX(0,delta-B13) | D13: =A13 | E13: =MIN(A13/C13,(4+B13)/5) | F13: =MAX(0,E13-A13)
A14: =INDEX(bounds,1) | B14: 0.25 | C14: =1-alpha*MAX(0,delta-B14) | D14: =A14 | E14: =MIN(A14/C14,(4+B14)/5) | F14: =MAX(0,E14-A14)
A15: =INDEX(bounds,1) | B15: 0.275 | C15: =1-alpha*MAX(0,delta-B15) | D15: =A15 | E15: =MIN(A15/C15,(4+B15)/5) | F15: =MAX(0,E15-A15)
... A19: =INDEX(bounds,1) | B19: 0.375 | C19: =1-alpha*MAX(0,delta-B19) | D19: =A19 | E19: =MIN(A19/C19,(4+B19)/5) | F19: =MAX(0,E19-A19)
A20: =INDEX(bounds,2) | B20: 0 | C20: =1-alpha*MAX(0,delta-B20) | D20: =A20 | E20: =MIN(A20/C20,(4+B20)/5) | F20: =MAX(0,E20-A20)
A21: =INDEX(bounds,2) | B21: 0.025 | C21: =1-alpha*MAX(0,delta-B21) | D21: =A21 | E21: =MIN(A21/C21,(4+B21)/5) | F21: =MAX(0,E21-A21)
A22: =INDEX(bounds,2) | B22: 0.05 | C22: =1-alpha*MAX(0,delta-B22) | D22: =A22 | E22: =MIN(A22/C22,(4+B22)/5) | F22: =MAX(0,E22-A22)
A23: =INDEX(bounds,2) | B23: 0.075 | C23: =1-alpha*MAX(0,delta-B23) | D23: =A23 | E23: =MIN(A23/C23,(4+B23)/5) | F23: =MAX(0,E23-A23)
A24: =INDEX(bounds,2) | B24: 0.1 | C24: =1-alpha*MAX(0,delta-B24) | D24: =A24 | E24: =MIN(A24/C24,(4+B24)/5) | F24: =MAX(0,E24-A24)
A25: =INDEX(bounds,2) | B25: 0.125 | C25: =1-alpha*MAX(0,delta-B25) | D25: =A25 | E25: =MIN(A25/C25,(4+B25)/5) | F25: =MAX(0,E25-A25)
A26: =INDEX(bounds,2) | B26: 0.15 | C26: =1-alpha*MAX(0,delta-B26) | D26: =A26 | E26: =MIN(A26/C26,(4+B26)/5) | F26: =MAX(0,E26-A26)
A27: =INDEX(bounds,2) | B27: 0.175 | C27: =1-alpha*MAX(0,delta-B27) | D27: =A27 | E27: =MIN(A27/C27,(4+B27)/5) | F27: =MAX(0,E27-A27)
A28: =INDEX(bounds,2) | B28: 0.2 | C28: =1-alpha*MAX(0,delta-B28) | D28: =A28 | E28: =MIN(A28/C28,(4+B28)/5) | F28: =MAX(0,E28-A28)
A29: =INDEX(bounds,2) | B29: 0.225 | C29: =1-alpha*MAX(0,delta-B29) | D29: =A29 | E29: =MIN(A29/C29,(4+B29)/5) | F29: =MAX(0,E29-A29)
A30: =INDEX(bounds,2) | B30: 0.25 | C30: =1-alpha*MAX(0,delta-B30) | D30: =A30 | E30: =MIN(A30/C30,(4+B30)/5) | F30: =MAX(0,E30-A30)
A31: =INDEX(bounds,2) | B31: 0.275 | C31: =1-alpha*MAX(0,delta-B31) | D31: =A31 | E31: =MIN(A31/C31,(4+B31)/5) | F31: =MAX(0,E31-A31)
... A35: =INDEX(bounds,2) | B35: 0.375 | C35: =1-alpha*MAX(0,delta-B35) | D35: =A35 | E35: =MIN(A35/C35,(4+B35)/5) | F35: =MAX(0,E35-A35)
A36: =INDEX(bounds,3) | B36: 0 | C36: =1-alpha*MAX(0,delta-B36) | D36: =A36 | E36: =MIN(A36/C36,(4+B36)/5) | F36: =MAX(0,E36-A36)
A37: =INDEX(bounds,3) | B37: 0.025 | C37: =1-alpha*MAX(0,delta-B37) | D37: =A37 | E37: =MIN(A37/C37,(4+B37)/5) | F37: =MAX(0,E37-A37)
A38: =INDEX(bounds,3) | B38: 0.05 | C38: =1-alpha*MAX(0,delta-B38) | D38: =A38 | E38: =MIN(A38/C38,(4+B38)/5) | F38: =MAX(0,E38-A38)
A39: =INDEX(bounds,3) | B39: 0.075 | C39: =1-alpha*MAX(0,delta-B39) | D39: =A39 | E39: =MIN(A39/C39,(4+B39)/5) | F39: =MAX(0,E39-A39)
A40: =INDEX(bounds,3) | B40: 0.1 | C40: =1-alpha*MAX(0,delta-B40) | D40: =A40 | E40: =MIN(A40/C40,(4+B40)/5) | F40: =MAX(0,E40-A40)
A41: =INDEX(bounds,3) | B41: 0.125 | C41: =1-alpha*MAX(0,delta-B41) | D41: =A41 | E41: =MIN(A41/C41,(4+B41)/5) | F41: =MAX(0,E41-A41)
A42: =INDEX(bounds,3) | B42: 0.15 | C42: =1-alpha*MAX(0,delta-B42) | D42: =A42 | E42: =MIN(A42/C42,(4+B42)/5) | F42: =MAX(0,E42-A42)
A43: =INDEX(bounds,3) | B43: 0.175 | C43: =1-alpha*MAX(0,delta-B43) | D43: =A43 | E43: =MIN(A43/C43,(4+B43)/5) | F43: =MAX(0,E43-A43)
A44: =INDEX(bounds,3) | B44: 0.2 | C44: =1-alpha*MAX(0,delta-B44) | D44: =A44 | E44: =MIN(A44/C44,(4+B44)/5) | F44: =MAX(0,E44-A44)
A45: =INDEX(bounds,3) | B45: 0.225 | C45: =1-alpha*MAX(0,delta-B45) | D45: =A45 | E45: =MIN(A45/C45,(4+B45)/5) | F45: =MAX(0,E45-A45)
A46: =INDEX(bounds,3) | B46: 0.25 | C46: =1-alpha*MAX(0,delta-B46) | D46: =A46 | E46: =MIN(A46/C46,(4+B46)/5) | F46: =MAX(0,E46-A46)
...

Sheet Experiment_sample
A1: First 1000 of 100 000 generated profiles (uniform scenario, data/generated/profiles_uniform.csv), every column is a formula
A2: Summary for this sample | E2: Full run, 100 000 profiles (scripts/simulation_experiment.py)
A3: Share of profiles with a penalty | D3: =AVERAGE(AH9:AH1008) | E3: 0.795
A4: Share of profiles whose level changed (H1) | D4: =AVERAGE(AI9:AI1008) | E4: 0.1125
A5: Mean reduction of the index | D5: =AVERAGE(AB9:AB1008)-AVERAGE(AE9:AE1008) | E5: 0.0249
A6: Share 'illusion of maturity' (H2) | D6: =AVERAGE(AJ9:AJ1008) | E6: 0.0595
A8: profile_id | B8: C_1 | C8: C_2 | D8: C_3 | E8: L1_1 | F8: L1_2 | G8: L2_1 | H8: L2_2 | I8: L2_3 | J8: L3_1 | K8: L3_2 | L8: L3_3 | M8: L4_1 | N8: L4_2 | O8: L4_3 | P8: I_1 | Q8: I_2 | R8: I_3 | S8: S_1 | T8: S_2 | U8: DM_C | V8: DM_L1 | W8: DM_L2 | X8: DM_L3 | Y8: DM_L4 | Z8: DM_I | AA8: DM_S | AB8: ADMI_base | AC8: DM_min | AD8: Penalty | AE8: ADMI | AF8: Level base | AG8: Level ADMI | AH8: Penalised | AI8: Level changed | AJ8: Illusion of maturity | AK8: Scalar incl. DM_I | AL8: Scalar level | AM8: Figure 2: ADMI_base if level changed | AN8: Figure 2: ADMI_base if level kept
A9: 1 | B9: 1 | C9: 4 | D9: 3 | E9: 5 | F9: 5 | G9: 5 | H9: 1 | I9: 4 | J9: 5 | K9: 2 | L9: 5 | M9: 5 | N9: 5 | O9: 4 | P9: 4 | Q9: 1 | R9: 4 | S9: 4 | T9: 2 | U9: =(AVERAGE(B9:D9)-1)/4 | V9: =(AVERAGE(E9:F9)-1)/4 | W9: =(AVERAGE(G9:I9)-1)/4 | X9: =(AVERAGE(J9:L9)-1)/4 | Y9: =(AVERAGE(M9:O9)-1)/4 | Z9: =(AVERAGE(P9:R9)-1)/4 | AA9: =(AVERAGE(S9:T9)-1)/4 | AB9: =AVERAGE(U9:Y9) | AC9: =MIN(U9:Y9) | AD9: =1-alpha*MAX(0,delta-AC9) | AE9: =AB9*AD9 | AF9: =1+COUNTIF(bounds,"<"&ROUND(AB9,12)) | AG9: =1+COUNTIF(bounds,"<"&ROUND(AE9,12)) | AH9: =IF(AD9<1,1,0) | AI9: =IF(AF9<>AG9,1,0) | AJ9: =IF(AND(AG9>=3,Z9<=0.2),1,0) | AK9: =AVERAGE(U9:Z9) | AL9: =1+COUNTIF(bounds,"<"&ROUND(AK9,12)) | AM9: =IF(AI9=1,AB9,NA()) | AN9: =IF(AI9=0,AB9,NA())
A10: 2 | B10: 2 | C10: 2 | D10: 4 | E10: 4 | F10: 4 | G10: 2 | H10: 2 | I10: 5 | J10: 4 | K10: 2 | L10: 5 | M10: 4 | N10: 1 | O10: 2 | P10: 4 | Q10: 1 | R10: 3 | S10: 4 | T10: 4 | U10: =(AVERAGE(B10:D10)-1)/4 | V10: =(AVERAGE(E10:F10)-1)/4 | W10: =(AVERAGE(G10:I10)-1)/4 | X10: =(AVERAGE(J10:L10)-1)/4 | Y10: =(AVERAGE(M10:O10)-1)/4 | Z10: =(AVERAGE(P10:R10)-1)/4 | AA10: =(AVERAGE(S10:T10)-1)/4 | AB10: =AVERAGE(U10:Y10) | AC10: =MIN(U10:Y10) | AD10: =1-alpha*MAX(0,delta-AC10) | AE10: =AB10*AD10 | AF10: =1+COUNTIF(bounds,"<"&ROUND(AB10,12)) | AG10: =1+COUNTIF(bounds,"<"&ROUND(AE10,12)) | AH10: =IF(AD10<1,1,0) | AI10: =IF(AF10<>AG10,1,0) | AJ10: =IF(AND(AG10>=3,Z10<=0.2),1,0) | AK10: =AVERAGE(U10:Z10) | AL10: =1+COUNTIF(bounds,"<"&ROUND(AK10,12)) | AM10: =IF(AI10=1,AB10,NA()) | AN10: =IF(AI10=0,AB10,NA())
A11: 3 | B11: 5 | C11: 1 | D11: 4 | E11: 4 | F11: 3 | G11: 1 | H11: 4 | I11: 3 | J11: 4 | K11: 2 | L11: 5 | M11: 4 | N11: 2 | O11: 3 | P11: 2 | Q11: 1 | R11: 1 | S11: 3 | T11: 4 | U11: =(AVERAGE(B11:D11)-1)/4 | V11: =(AVERAGE(E11:F11)-1)/4 | W11: =(AVERAGE(G11:I11)-1)/4 | X11: =(AVERAGE(J11:L11)-1)/4 | Y11: =(AVERAGE(M11:O11)-1)/4 | Z11: =(AVERAGE(P11:R11)-1)/4 | AA11: =(AVERAGE(S11:T11)-1)/4 | AB11: =AVERAGE(U11:Y11) | AC11: =MIN(U11:Y11) | AD11: =1-alpha*MAX(0,delta-AC11) | AE11: =AB11*AD11 | AF11: =1+COUNTIF(bounds,"<"&ROUND(AB11,12)) | AG11: =1+COUNTIF(bounds,"<"&ROUND(AE11,12)) | AH11: =IF(AD11<1,1,0) | AI11: =IF(AF11<>AG11,1,0) | AJ11: =IF(AND(AG11>=3,Z11<=0.2),1,0) | AK11: =AVERAGE(U11:Z11) | AL11: =1+COUNTIF(bounds,"<"&ROUND(AK11,12)) | AM11: =IF(AI11=1,AB11,NA()) | AN11: =IF(AI11=0,AB11,NA())
A12: 4 | B12: 2 | C12: 5 | D12: 5 | E12: 2 | F12: 4 | G12: 1 | H12: 2 | I12: 4 | J12: 5 | K12: 4 | L12: 1 | M12: 2 | N12: 3 | O12: 3 | P12: 2 | Q12: 2 | R12: 5 | S12: 1 | T12: 1 | U12: =(AVERAGE(B12:D12)-1)/4 | V12: =(AVERAGE(E12:F12)-1)/4 | W12: =(AVERAGE(G12:I12)-1)/4 | X12: =(AVERAGE(J12:L12)-1)/4 | Y12: =(AVERAGE(M12:O12)-1)/4 | Z12: =(AVERAGE(P12:R12)-1)/4 | AA12: =(AVERAGE(S12:T12)-1)/4 | AB12: =AVERAGE(U12:Y12) | AC12: =MIN(U12:Y12) | AD12: =1-alpha*MAX(0,delta-AC12) | AE12: =AB12*AD12 | AF12: =1+COUNTIF(bounds,"<"&ROUND(AB12,12)) | AG12: =1+COUNTIF(bounds,"<"&ROUND(AE12,12)) | AH12: =IF(AD12<1,1,0) | AI12: =IF(AF12<>AG12,1,0) | AJ12: =IF(AND(AG12>=3,Z12<=0.2),1,0) | AK12: =AVERAGE(U12:Z12) | AL12: =1+COUNTIF(bounds,"<"&ROUND(AK12,12)) | AM12: =IF(AI12=1,AB12,NA()) | AN12: =IF(AI12=0,AB12,NA())
A13: 5 | B13: 4 | C13: 4 | D13: 3 | E13: 4 | F13: 5 | G13: 5 | H13: 1 | I13: 3 | J13: 5 | K13: 4 | L13: 2 | M13: 4 | N13: 4 | O13: 5 | P13: 5 | Q13: 5 | R13: 2 | S13: 1 | T13: 4 | U13: =(AVERAGE(B13:D13)-1)/4 | V13: =(AVERAGE(E13:F13)-1)/4 | W13: =(AVERAGE(G13:I13)-1)/4 | X13: =(AVERAGE(J13:L13)-1)/4 | Y13: =(AVERAGE(M13:O13)-1)/4 | Z13: =(AVERAGE(P13:R13)-1)/4 | AA13: =(AVERAGE(S13:T13)-1)/4 | AB13: =AVERAGE(U13:Y13) | AC13: =MIN(U13:Y13) | AD13: =1-alpha*MAX(0,delta-AC13) | AE13: =AB13*AD13 | AF13: =1+COUNTIF(bounds,"<"&ROUND(AB13,12)) | AG13: =1+COUNTIF(bounds,"<"&ROUND(AE13,12)) | AH13: =IF(AD13<1,1,0) | AI13: =IF(AF13<>AG13,1,0) | AJ13: =IF(AND(AG13>=3,Z13<=0.2),1,0) | AK13: =AVERAGE(U13:Z13) | AL13: =1+COUNTIF(bounds,"<"&ROUND(AK13,12)) | AM13: =IF(AI13=1,AB13,NA()) | AN13: =IF(AI13=0,AB13,NA())
A14: 6 | B14: 5 | C14: 3 | D14: 2 | E14: 5 | F14: 1 | G14: 2 | H14: 1 | I14: 5 | J14: 3 | K14: 4 | L14: 5 | M14: 3 | N14: 1 | O14: 2 | P14: 4 | Q14: 2 | R14: 2 | S14: 5 | T14: 5 | U14: =(AVERAGE(B14:D14)-1)/4 | V14: =(AVERAGE(E14:F14)-1)/4 | W14: =(AVERAGE(G14:I14)-1)/4 | X14: =(AVERAGE(J14:L14)-1)/4 | Y14: =(AVERAGE(M14:O14)-1)/4 | Z14: =(AVERAGE(P14:R14)-1)/4 | AA14: =(AVERAGE(S14:T14)-1)/4 | AB14: =AVERAGE(U14:Y14) | AC14: =MIN(U14:Y14) | AD14: =1-alpha*MAX(0,delta-AC14) | AE14: =AB14*AD14 | AF14: =1+COUNTIF(bounds,"<"&ROUND(AB14,12)) | AG14: =1+COUNTIF(bounds,"<"&ROUND(AE14,12)) | AH14: =IF(AD14<1,1,0) | AI14: =IF(AF14<>AG14,1,0) | AJ14: =IF(AND(AG14>=3,Z14<=0.2),1,0) | AK14: =AVERAGE(U14:Z14) | AL14: =1+COUNTIF(bounds,"<"&ROUND(AK14,12)) | AM14: =IF(AI14=1,AB14,NA()) | AN14: =IF(AI14=0,AB14,NA())
A15: 7 | B15: 2 | C15: 2 | D15: 3 | E15: 3 | F15: 2 | G15: 2 | H15: 4 | I15: 5 | J15: 1 | K15: 4 | L15: 5 | M15: 5 | N15: 2 | O15: 2 | P15: 4 | Q15: 2 | R15: 1 | S15: 2 | T15: 3 | U15: =(AVERAGE(B15:D15)-1)/4 | V15: =(AVERAGE(E15:F15)-1)/4 | W15: =(AVERAGE(G15:I15)-1)/4 | X15: =(AVERAGE(J15:L15)-1)/4 | Y15: =(AVERAGE(M15:O15)-1)/4 | Z15: =(AVERAGE(P15:R15)-1)/4 | AA15: =(AVERAGE(S15:T15)-1)/4 | AB15: =AVERAGE(U15:Y15) | AC15: =MIN(U15:Y15) | AD15: =1-alpha*MAX(0,delta-AC15) | AE15: =AB15*AD15 | AF15: =1+COUNTIF(bounds,"<"&ROUND(AB15,12)) | AG15: =1+COUNTIF(bounds,"<"&ROUND(AE15,12)) | AH15: =IF(AD15<1,1,0) | AI15: =IF(AF15<>AG15,1,0) | AJ15: =IF(AND(AG15>=3,Z15<=0.2),1,0) | AK15: =AVERAGE(U15:Z15) | AL15: =1+COUNTIF(bounds,"<"&ROUND(AK15,12)) | AM15: =IF(AI15=1,AB15,NA()) | AN15: =IF(AI15=0,AB15,NA())
A16: 8 | B16: 3 | C16: 4 | D16: 1 | E16: 2 | F16: 2 | G16: 4 | H16: 3 | I16: 4 | J16: 5 | K16: 2 | L16: 1 | M16: 3 | N16: 1 | O16: 4 | P16: 5 | Q16: 4 | R16: 2 | S16: 4 | T16: 4 | U16: =(AVERAGE(B16:D16)-1)/4 | V16: =(AVERAGE(E16:F16)-1)/4 | W16: =(AVERAGE(G16:I16)-1)/4 | X16: =(AVERAGE(J16:L16)-1)/4 | Y16: =(AVERAGE(M16:O16)-1)/4 | Z16: =(AVERAGE(P16:R16)-1)/4 | AA16: =(AVERAGE(S16:T16)-1)/4 | AB16: =AVERAGE(U16:Y16) | AC16: =MIN(U16:Y16) | AD16: =1-alpha*MAX(0,delta-AC16) | AE16: =AB16*AD16 | AF16: =1+COUNTIF(bounds,"<"&ROUND(AB16,12)) | AG16: =1+COUNTIF(bounds,"<"&ROUND(AE16,12)) | AH16: =IF(AD16<1,1,0) | AI16: =IF(AF16<>AG16,1,0) | AJ16: =IF(AND(AG16>=3,Z16<=0.2),1,0) | AK16: =AVERAGE(U16:Z16) | AL16: =1+COUNTIF(bounds,"<"&ROUND(AK16,12)) | AM16: =IF(AI16=1,AB16,NA()) | AN16: =IF(AI16=0,AB16,NA())
A17: 9 | B17: 3 | C17: 2 | D17: 1 | E17: 1 | F17: 3 | G17: 5 | H17: 2 | I17: 2 | J17: 2 | K17: 3 | L17: 2 | M17: 4 | N17: 1 | O17: 2 | P17: 3 | Q17: 5 | R17: 4 | S17: 1 | T17: 3 | U17: =(AVERAGE(B17:D17)-1)/4 | V17: =(AVERAGE(E17:F17)-1)/4 | W17: =(AVERAGE(G17:I17)-1)/4 | X17: =(AVERAGE(J17:L17)-1)/4 | Y17: =(AVERAGE(M17:O17)-1)/4 | Z17: =(AVERAGE(P17:R17)-1)/4 | AA17: =(AVERAGE(S17:T17)-1)/4 | AB17: =AVERAGE(U17:Y17) | AC17: =MIN(U17:Y17) | AD17: =1-alpha*MAX(0,delta-AC17) | AE17: =AB17*AD17 | AF17: =1+COUNTIF(bounds,"<"&ROUND(AB17,12)) | AG17: =1+COUNTIF(bounds,"<"&ROUND(AE17,12)) | AH17: =IF(AD17<1,1,0) | AI17: =IF(AF17<>AG17,1,0) | AJ17: =IF(AND(AG17>=3,Z17<=0.2),1,0) | AK17: =AVERAGE(U17:Z17) | AL17: =1+COUNTIF(bounds,"<"&ROUND(AK17,12)) | AM17: =IF(AI17=1,AB17,NA()) | AN17: =IF(AI17=0,AB17,NA())
A18: 10 | B18: 3 | C18: 3 | D18: 2 | E18: 5 | F18: 1 | G18: 5 | H18: 3 | I18: 4 | J18: 3 | K18: 4 | L18: 3 | M18: 3 | N18: 2 | O18: 4 | P18: 3 | Q18: 5 | R18: 2 | S18: 3 | T18: 1 | U18: =(AVERAGE(B18:D18)-1)/4 | V18: =(AVERAGE(E18:F18)-1)/4 | W18: =(AVERAGE(G18:I18)-1)/4 | X18: =(AVERAGE(J18:L18)-1)/4 | Y18: =(AVERAGE(M18:O18)-1)/4 | Z18: =(AVERAGE(P18:R18)-1)/4 | AA18: =(AVERAGE(S18:T18)-1)/4 | AB18: =AVERAGE(U18:Y18) | AC18: =MIN(U18:Y18) | AD18: =1-alpha*MAX(0,delta-AC18) | AE18: =AB18*AD18 | AF18: =1+COUNTIF(bounds,"<"&ROUND(AB18,12)) | AG18: =1+COUNTIF(bounds,"<"&ROUND(AE18,12)) | AH18: =IF(AD18<1,1,0) | AI18: =IF(AF18<>AG18,1,0) | AJ18: =IF(AND(AG18>=3,Z18<=0.2),1,0) | AK18: =AVERAGE(U18:Z18) | AL18: =1+COUNTIF(bounds,"<"&ROUND(AK18,12)) | AM18: =IF(AI18=1,AB18,NA()) | AN18: =IF(AI18=0,AB18,NA())
A19: 11 | B19: 2 | C19: 5 | D19: 4 | E19: 4 | F19: 4 | G19: 5 | H19: 1 | I19: 3 | J19: 3 | K19: 4 | L19: 1 | M19: 5 | N19: 2 | O19: 2 | P19: 2 | Q19: 2 | R19: 3 | S19: 2 | T19: 4 | U19: =(AVERAGE(B19:D19)-1)/4 | V19: =(AVERAGE(E19:F19)-1)/4 | W19: =(AVERAGE(G19:I19)-1)/4 | X19: =(AVERAGE(J19:L19)-1)/4 | Y19: =(AVERAGE(M19:O19)-1)/4 | Z19: =(AVERAGE(P19:R19)-1)/4 | AA19: =(AVERAGE(S19:T19)-1)/4 | AB19: =AVERAGE(U19:Y19) | AC19: =MIN(U19:Y19) | AD19: =1-alpha*MAX(0,delta-AC19) | AE19: =AB19*AD19 | AF19: =1+COUNTIF(bounds,"<"&ROUND(AB19,12)) | AG19: =1+COUNTIF(bounds,"<"&ROUND(AE19,12)) | AH19: =IF(AD19<1,1,0) | AI19: =IF(AF19<>AG19,1,0) | AJ19: =IF(AND(AG19>=3,Z19<=0.2),1,0) | AK19: =AVERAGE(U19:Z19) | AL19: =1+COUNTIF(bounds,"<"&ROUND(AK19,12)) | AM19: =IF(AI19=1,AB19,NA()) | AN19: =IF(AI19=0,AB19,NA())
A20: 12 | B20: 4 | C20: 2 | D20: 5 | E20: 1 | F20: 4 | G20: 2 | H20: 3 | I20: 2 | J20: 1 | K20: 5 | L20: 1 | M20: 3 | N20: 5 | O20: 2 | P20: 3 | Q20: 5 | R20: 4 | S20: 3 | T20: 2 | U20: =(AVERAGE(B20:D20)-1)/4 | V20: =(AVERAGE(E20:F20)-1)/4 | W20: =(AVERAGE(G20:I20)-1)/4 | X20: =(AVERAGE(J20:L20)-1)/4 | Y20: =(AVERAGE(M20:O20)-1)/4 | Z20: =(AVERAGE(P20:R20)-1)/4 | AA20: =(AVERAGE(S20:T20)-1)/4 | AB20: =AVERAGE(U20:Y20) | AC20: =MIN(U20:Y20) | AD20: =1-alpha*MAX(0,delta-AC20) | AE20: =AB20*AD20 | AF20: =1+COUNTIF(bounds,"<"&ROUND(AB20,12)) | AG20: =1+COUNTIF(bounds,"<"&ROUND(AE20,12)) | AH20: =IF(AD20<1,1,0) | AI20: =IF(AF20<>AG20,1,0) | AJ20: =IF(AND(AG20>=3,Z20<=0.2),1,0) | AK20: =AVERAGE(U20:Z20) | AL20: =1+COUNTIF(bounds,"<"&ROUND(AK20,12)) | AM20: =IF(AI20=1,AB20,NA()) | AN20: =IF(AI20=0,AB20,NA())
... A1008: 1000 | B1008: 5 | C1008: 3 | D1008: 5 | E1008: 2 | F1008: 3 | G1008: 3 | H1008: 1 | I1008: 1 | J1008: 1 | K1008: 3 | L1008: 2 | M1008: 1 | N1008: 4 | O1008: 1 | P1008: 5 | Q1008: 5 | R1008: 4 | S1008: 5 | T1008: 3 | U1008: =(AVERAGE(B1008:D1008)-1)/4 | V1008: =(AVERAGE(E1008:F1008)-1)/4 | W1008: =(AVERAGE(G1008:I1008)-1)/4 | X1008: =(AVERAGE(J1008:L1008)-1)/4 | Y1008: =(AVERAGE(M1008:O1008)-1)/4 | Z1008: =(AVERAGE(P1008:R1008)-1)/4 | AA1008: =(AVERAGE(S1008:T1008)-1)/4 | AB1008: =AVERAGE(U1008:Y1008) | AC1008: =MIN(U1008:Y1008) | AD1008: =1-alpha*MAX(0,delta-AC1008) | AE1008: =AB1008*AD1008 | AF1008: =1+COUNTIF(bounds,"<"&ROUND(AB1008,12)) | AG1008: =1+COUNTIF(bounds,"<"&ROUND(AE1008,12)) | AH1008: =IF(AD1008<1,1,0) | AI1008: =IF(AF1008<>AG1008,1,0) | AJ1008: =IF(AND(AG1008>=3,Z1008<=0.2),1,0) | AK1008: =AVERAGE(U1008:Z1008) | AL1008: =1+COUNTIF(bounds,"<"&ROUND(AK1008,12)) | AM1008: =IF(AI1008=1,AB1008,NA()) | AN1008: =IF(AI1008=0,AB1008,NA())

Sheet Figure_2_band
A1: Figure 2. Where the weak-link penalty changes the maturity level (equation 7; points: first 1 000 profiles of the uniform scenario)
A2: Between the solid line (bound b) and the dashed line (upper limit of equation 7) the penalty moves the profile one level down. Change alpha or delta on Parameters to see the band move.
A4: DM_min | B4: Bound 0.40 | C4: Upper limit for 0.40 | D4: Bound 0.60 | E4: Upper limit for 0.60 | F4: Bound 0.20 | G4: Upper limit for 0.20
A5: 0 | B5: =INDEX(bounds,2) | C5: =MIN(B5/(1-alpha*MAX(0,delta-A5)),(4+A5)/5) | D5: =INDEX(bounds,3) | E5: =MIN(D5/(1-alpha*MAX(0,delta-A5)),(4+A5)/5) | F5: =INDEX(bounds,1) | G5: =MIN(F5/(1-alpha*MAX(0,delta-A5)),(4+A5)/5)
A6: 0.025 | B6: =INDEX(bounds,2) | C6: =MIN(B6/(1-alpha*MAX(0,delta-A6)),(4+A6)/5) | D6: =INDEX(bounds,3) | E6: =MIN(D6/(1-alpha*MAX(0,delta-A6)),(4+A6)/5) | F6: =INDEX(bounds,1) | G6: =MIN(F6/(1-alpha*MAX(0,delta-A6)),(4+A6)/5)
A7: 0.05 | B7: =INDEX(bounds,2) | C7: =MIN(B7/(1-alpha*MAX(0,delta-A7)),(4+A7)/5) | D7: =INDEX(bounds,3) | E7: =MIN(D7/(1-alpha*MAX(0,delta-A7)),(4+A7)/5) | F7: =INDEX(bounds,1) | G7: =MIN(F7/(1-alpha*MAX(0,delta-A7)),(4+A7)/5)
A8: 0.075 | B8: =INDEX(bounds,2) | C8: =MIN(B8/(1-alpha*MAX(0,delta-A8)),(4+A8)/5) | D8: =INDEX(bounds,3) | E8: =MIN(D8/(1-alpha*MAX(0,delta-A8)),(4+A8)/5) | F8: =INDEX(bounds,1) | G8: =MIN(F8/(1-alpha*MAX(0,delta-A8)),(4+A8)/5)
A9: 0.1 | B9: =INDEX(bounds,2) | C9: =MIN(B9/(1-alpha*MAX(0,delta-A9)),(4+A9)/5) | D9: =INDEX(bounds,3) | E9: =MIN(D9/(1-alpha*MAX(0,delta-A9)),(4+A9)/5) | F9: =INDEX(bounds,1) | G9: =MIN(F9/(1-alpha*MAX(0,delta-A9)),(4+A9)/5)
A10: 0.125 | B10: =INDEX(bounds,2) | C10: =MIN(B10/(1-alpha*MAX(0,delta-A10)),(4+A10)/5) | D10: =INDEX(bounds,3) | E10: =MIN(D10/(1-alpha*MAX(0,delta-A10)),(4+A10)/5) | F10: =INDEX(bounds,1) | G10: =MIN(F10/(1-alpha*MAX(0,delta-A10)),(4+A10)/5)
A11: 0.15 | B11: =INDEX(bounds,2) | C11: =MIN(B11/(1-alpha*MAX(0,delta-A11)),(4+A11)/5) | D11: =INDEX(bounds,3) | E11: =MIN(D11/(1-alpha*MAX(0,delta-A11)),(4+A11)/5) | F11: =INDEX(bounds,1) | G11: =MIN(F11/(1-alpha*MAX(0,delta-A11)),(4+A11)/5)
A12: 0.175 | B12: =INDEX(bounds,2) | C12: =MIN(B12/(1-alpha*MAX(0,delta-A12)),(4+A12)/5) | D12: =INDEX(bounds,3) | E12: =MIN(D12/(1-alpha*MAX(0,delta-A12)),(4+A12)/5) | F12: =INDEX(bounds,1) | G12: =MIN(F12/(1-alpha*MAX(0,delta-A12)),(4+A12)/5)
A13: 0.2 | B13: =INDEX(bounds,2) | C13: =MIN(B13/(1-alpha*MAX(0,delta-A13)),(4+A13)/5) | D13: =INDEX(bounds,3) | E13: =MIN(D13/(1-alpha*MAX(0,delta-A13)),(4+A13)/5) | F13: =INDEX(bounds,1) | G13: =MIN(F13/(1-alpha*MAX(0,delta-A13)),(4+A13)/5)
A14: 0.225 | B14: =INDEX(bounds,2) | C14: =MIN(B14/(1-alpha*MAX(0,delta-A14)),(4+A14)/5) | D14: =INDEX(bounds,3) | E14: =MIN(D14/(1-alpha*MAX(0,delta-A14)),(4+A14)/5) | F14: =INDEX(bounds,1) | G14: =MIN(F14/(1-alpha*MAX(0,delta-A14)),(4+A14)/5)
A15: 0.25 | B15: =INDEX(bounds,2) | C15: =MIN(B15/(1-alpha*MAX(0,delta-A15)),(4+A15)/5) | D15: =INDEX(bounds,3) | E15: =MIN(D15/(1-alpha*MAX(0,delta-A15)),(4+A15)/5) | F15: =INDEX(bounds,1) | G15: =MIN(F15/(1-alpha*MAX(0,delta-A15)),(4+A15)/5)
A16: 0.275 | B16: =INDEX(bounds,2) | C16: =MIN(B16/(1-alpha*MAX(0,delta-A16)),(4+A16)/5) | D16: =INDEX(bounds,3) | E16: =MIN(D16/(1-alpha*MAX(0,delta-A16)),(4+A16)/5) | F16: =INDEX(bounds,1) | G16: =MIN(F16/(1-alpha*MAX(0,delta-A16)),(4+A16)/5)
... A20: 0.375 | B20: =INDEX(bounds,2) | C20: =MIN(B20/(1-alpha*MAX(0,delta-A20)),(4+A20)/5) | D20: =INDEX(bounds,3) | E20: =MIN(D20/(1-alpha*MAX(0,delta-A20)),(4+A20)/5) | F20: =INDEX(bounds,1) | G20: =MIN(F20/(1-alpha*MAX(0,delta-A20)),(4+A20)/5)

Sheet Figure_3_map
A1: Figure 3. Diagnostic map (ADMI, DM_I): sample profiles and the five situations of Table 6
A2: Lower right zone (ADMI above the level-3 bound, DM_I at most 0.20) is the 'illusion of maturity': equipped layers without integration.
A4: Situation | B4: ADMI | C4: DM_I
A5: Compliance trap | B5: =Diagnostic_situations!L4 | C5: =Diagnostic_situations!G4
A6: External EU pressure | B6: =Diagnostic_situations!L5 | C6: =Diagnostic_situations!G5
A7: Absorptive limiter | B7: =Diagnostic_situations!L6 | C7: =Diagnostic_situations!G6
A8: Aware mismatch | B8: =Diagnostic_situations!L7 | C8: =Diagnostic_situations!G7
A9: Illusion of maturity | B9: =Diagnostic_situations!L8 | C9: =Diagnostic_situations!G8
A12: Guide lines | B12: x | C12: y
A13: level-3 bound | B13: =INDEX(bounds,2) | C13: 0
A14: level-3 bound | B14: =INDEX(bounds,2) | C14: 1
A15: DM_I = 0.20 | B15: 0 | C15: 0.2
A16: DM_I = 0.20 | B16: 1 | C16: 0.2
